2017-02-26 21:45:53,421 [Thread-2:9792] [django.request:182] [base:get_response] [WARNING]- Not Found: /
2017-02-26 21:46:02,809 [Thread-3:11896] [django.request:182] [base:get_response] [WARNING]- Not Found: /lo]
2017-02-26 21:46:07,081 [Thread-11:13480] [django.request:284] [base:handle_uncaught_exception] [ERROR]- Internal Server Error: /login
Traceback (most recent call last):
  File "D:\python_env\dssms_env_for_win\lib\site-packages\django\core\handlers\base.py", line 149, in get_response
    response = self.process_exception_by_middleware(e, request)
  File "D:\python_env\dssms_env_for_win\lib\site-packages\django\core\handlers\base.py", line 147, in get_response
    response = wrapped_callback(request, *callback_args, **callback_kwargs)
  File "D:\python_env\dssms_1_9_12\company\views.py", line 139, in login
    return render(request, 'login.html', {'company_login':company_login, 'error':''})
UnboundLocalError: local variable 'company_login' referenced before assignment
2017-02-26 21:47:17,470 [Thread-2:11708] [django.request:284] [base:handle_uncaught_exception] [ERROR]- Internal Server Error: /login
Traceback (most recent call last):
  File "D:\python_env\dssms_env_for_win\lib\site-packages\django\core\handlers\base.py", line 149, in get_response
    response = self.process_exception_by_middleware(e, request)
  File "D:\python_env\dssms_env_for_win\lib\site-packages\django\core\handlers\base.py", line 147, in get_response
    response = wrapped_callback(request, *callback_args, **callback_kwargs)
  File "D:\python_env\dssms_1_9_12\company\views.py", line 139, in login
    return render(request, 'login.html', {'company_login':company_login, 'error':''})
UnboundLocalError: local variable 'company_login' referenced before assignment
2017-02-26 21:47:18,688 [Thread-3:3564] [django.request:284] [base:handle_uncaught_exception] [ERROR]- Internal Server Error: /login
Traceback (most recent call last):
  File "D:\python_env\dssms_env_for_win\lib\site-packages\django\core\handlers\base.py", line 149, in get_response
    response = self.process_exception_by_middleware(e, request)
  File "D:\python_env\dssms_env_for_win\lib\site-packages\django\core\handlers\base.py", line 147, in get_response
    response = wrapped_callback(request, *callback_args, **callback_kwargs)
  File "D:\python_env\dssms_1_9_12\company\views.py", line 139, in login
    return render(request, 'login.html', {'company_login':company_login, 'error':''})
UnboundLocalError: local variable 'company_login' referenced before assignment
2017-02-26 21:48:31,727 [Thread-2:12412] [django.request:284] [base:handle_uncaught_exception] [ERROR]- Internal Server Error: /login
Traceback (most recent call last):
  File "D:\python_env\dssms_env_for_win\lib\site-packages\django\core\handlers\base.py", line 149, in get_response
    response = self.process_exception_by_middleware(e, request)
  File "D:\python_env\dssms_env_for_win\lib\site-packages\django\core\handlers\base.py", line 147, in get_response
    response = wrapped_callback(request, *callback_args, **callback_kwargs)
  File "D:\python_env\dssms_1_9_12\company\views.py", line 139, in login
    return render(request, 'login.html', {'company_login':company_login, 'error':''})
  File "D:\python_env\dssms_env_for_win\lib\site-packages\django\shortcuts.py", line 67, in render
    template_name, context, request=request, using=using)
  File "D:\python_env\dssms_env_for_win\lib\site-packages\django\template\loader.py", line 97, in render_to_string
    return template.render(context, request)
  File "D:\python_env\dssms_env_for_win\lib\site-packages\django\template\backends\django.py", line 97, in render
    reraise(exc, self.backend)
  File "D:\python_env\dssms_env_for_win\lib\site-packages\django\template\backends\django.py", line 118, in reraise
    six.reraise(exc.__class__, new, sys.exc_info()[2])
  File "D:\python_env\dssms_env_for_win\lib\site-packages\django\template\backends\django.py", line 95, in render
    return self.template.render(context)
  File "D:\python_env\dssms_env_for_win\lib\site-packages\django\template\base.py", line 206, in render
    return self._render(context)
  File "D:\python_env\dssms_env_for_win\lib\site-packages\django\template\base.py", line 197, in _render
    return self.nodelist.render(context)
  File "D:\python_env\dssms_env_for_win\lib\site-packages\django\template\base.py", line 992, in render
    bit = node.render_annotated(context)
  File "D:\python_env\dssms_env_for_win\lib\site-packages\django\template\base.py", line 959, in render_annotated
    return self.render(context)
  File "D:\python_env\dssms_env_for_win\lib\site-packages\django\template\loader_tags.py", line 151, in render
    compiled_parent = self.get_parent(context)
  File "D:\python_env\dssms_env_for_win\lib\site-packages\django\template\loader_tags.py", line 148, in get_parent
    return self.find_template(parent, context)
  File "D:\python_env\dssms_env_for_win\lib\site-packages\django\template\loader_tags.py", line 128, in find_template
    template_name, skip=history,
  File "D:\python_env\dssms_env_for_win\lib\site-packages\django\template\engine.py", line 169, in find_template
    raise TemplateDoesNotExist(name, tried=tried)
TemplateDoesNotExist: blogin.html
2017-02-26 21:49:26,875 [Thread-20:1520] [django.request:182] [base:get_response] [WARNING]- Not Found: /favicon.ico
2017-02-26 23:25:16,407 [Thread-2:13516] [django.request:182] [base:get_response] [WARNING]- Not Found: /
