2017-02-28 23:23:56,611 [Thread-7:6572] [django.request:182] [base:get_response] [WARNING]- Not Found: /index/cindex.html
2017-02-28 23:23:56,658 [Thread-8:1296] [django.request:182] [base:get_response] [WARNING]- Not Found: /favicon.ico
2017-02-28 23:23:58,944 [Thread-9:9816] [django.request:284] [base:handle_uncaught_exception] [ERROR]- Internal Server Error: /
Traceback (most recent call last):
  File "D:\python_env\dssms_env_for_win\lib\site-packages\django\core\handlers\base.py", line 158, in get_response
    % (callback.__module__, view_name))
ValueError: The view company.views.do_login didn't return an HttpResponse object. It returned None instead.
2017-02-28 23:25:24,687 [Thread-15:13416] [django.request:284] [base:handle_uncaught_exception] [ERROR]- Internal Server Error: /
Traceback (most recent call last):
  File "D:\python_env\dssms_env_for_win\lib\site-packages\django\core\handlers\base.py", line 158, in get_response
    % (callback.__module__, view_name))
ValueError: The view company.views.do_login didn't return an HttpResponse object. It returned None instead.
2017-02-28 23:26:46,559 [Thread-7:4424] [django.request:182] [base:get_response] [WARNING]- Not Found: /
2017-02-28 23:26:54,940 [Thread-8:5136] [django.request:182] [base:get_response] [WARNING]- Not Found: /
2017-02-28 23:29:39,187 [Thread-7:13336] [django.request:284] [base:handle_uncaught_exception] [ERROR]- Internal Server Error: /login
Traceback (most recent call last):
  File "D:\python_env\dssms_env_for_win\lib\site-packages\django\core\handlers\base.py", line 158, in get_response
    % (callback.__module__, view_name))
ValueError: The view company.views.do_login didn't return an HttpResponse object. It returned None instead.
2017-02-28 23:33:46,625 [Thread-8:840] [django.request:284] [base:handle_uncaught_exception] [ERROR]- Internal Server Error: /login/
Traceback (most recent call last):
  File "D:\python_env\dssms_env_for_win\lib\site-packages\django\core\handlers\base.py", line 158, in get_response
    % (callback.__module__, view_name))
ValueError: The view company.views.do_login didn't return an HttpResponse object. It returned None instead.
2017-02-28 23:33:55,444 [Thread-7:12092] [django.request:284] [base:handle_uncaught_exception] [ERROR]- Internal Server Error: /login/
Traceback (most recent call last):
  File "D:\python_env\dssms_env_for_win\lib\site-packages\django\core\handlers\base.py", line 158, in get_response
    % (callback.__module__, view_name))
ValueError: The view company.views.do_login didn't return an HttpResponse object. It returned None instead.
2017-02-28 23:41:27,108 [Thread-7:13392] [django.request:284] [base:handle_uncaught_exception] [ERROR]- Internal Server Error: /login/
Traceback (most recent call last):
  File "D:\python_env\dssms_env_for_win\lib\site-packages\django\core\handlers\base.py", line 158, in get_response
    % (callback.__module__, view_name))
ValueError: The view company.views.do_login didn't return an HttpResponse object. It returned None instead.
2017-02-28 23:41:30,907 [Thread-8:6764] [django.request:284] [base:handle_uncaught_exception] [ERROR]- Internal Server Error: /login/
Traceback (most recent call last):
  File "D:\python_env\dssms_env_for_win\lib\site-packages\django\core\handlers\base.py", line 158, in get_response
    % (callback.__module__, view_name))
ValueError: The view company.views.do_login didn't return an HttpResponse object. It returned None instead.
2017-02-28 23:41:31,698 [Thread-9:11808] [django.request:284] [base:handle_uncaught_exception] [ERROR]- Internal Server Error: /login/
Traceback (most recent call last):
  File "D:\python_env\dssms_env_for_win\lib\site-packages\django\core\handlers\base.py", line 158, in get_response
    % (callback.__module__, view_name))
ValueError: The view company.views.do_login didn't return an HttpResponse object. It returned None instead.
2017-02-28 23:41:32,378 [Thread-10:11768] [django.request:284] [base:handle_uncaught_exception] [ERROR]- Internal Server Error: /login/
Traceback (most recent call last):
  File "D:\python_env\dssms_env_for_win\lib\site-packages\django\core\handlers\base.py", line 158, in get_response
    % (callback.__module__, view_name))
ValueError: The view company.views.do_login didn't return an HttpResponse object. It returned None instead.
2017-02-28 23:41:32,971 [Thread-11:13832] [django.request:284] [base:handle_uncaught_exception] [ERROR]- Internal Server Error: /login/
Traceback (most recent call last):
  File "D:\python_env\dssms_env_for_win\lib\site-packages\django\core\handlers\base.py", line 158, in get_response
    % (callback.__module__, view_name))
ValueError: The view company.views.do_login didn't return an HttpResponse object. It returned None instead.
2017-02-28 23:41:33,285 [Thread-12:7372] [django.request:284] [base:handle_uncaught_exception] [ERROR]- Internal Server Error: /login/
Traceback (most recent call last):
  File "D:\python_env\dssms_env_for_win\lib\site-packages\django\core\handlers\base.py", line 158, in get_response
    % (callback.__module__, view_name))
ValueError: The view company.views.do_login didn't return an HttpResponse object. It returned None instead.
2017-02-28 23:41:33,627 [Thread-13:14024] [django.request:284] [base:handle_uncaught_exception] [ERROR]- Internal Server Error: /login/
Traceback (most recent call last):
  File "D:\python_env\dssms_env_for_win\lib\site-packages\django\core\handlers\base.py", line 158, in get_response
    % (callback.__module__, view_name))
ValueError: The view company.views.do_login didn't return an HttpResponse object. It returned None instead.
2017-02-28 23:42:30,502 [Thread-7:8536] [django.request:284] [base:handle_uncaught_exception] [ERROR]- Internal Server Error: /login/
Traceback (most recent call last):
  File "D:\python_env\dssms_env_for_win\lib\site-packages\django\core\handlers\base.py", line 158, in get_response
    % (callback.__module__, view_name))
ValueError: The view company.views.do_login didn't return an HttpResponse object. It returned None instead.
2017-02-28 23:43:19,206 [Thread-7:5908] [django.request:284] [base:handle_uncaught_exception] [ERROR]- Internal Server Error: /login/
Traceback (most recent call last):
  File "D:\python_env\dssms_env_for_win\lib\site-packages\django\core\handlers\base.py", line 158, in get_response
    % (callback.__module__, view_name))
ValueError: The view company.views.do_login didn't return an HttpResponse object. It returned None instead.
2017-02-28 23:43:19,969 [Thread-8:10932] [django.request:284] [base:handle_uncaught_exception] [ERROR]- Internal Server Error: /login/
Traceback (most recent call last):
  File "D:\python_env\dssms_env_for_win\lib\site-packages\django\core\handlers\base.py", line 158, in get_response
    % (callback.__module__, view_name))
ValueError: The view company.views.do_login didn't return an HttpResponse object. It returned None instead.
2017-02-28 23:43:28,391 [Thread-10:7900] [django.request:284] [base:handle_uncaught_exception] [ERROR]- Internal Server Error: /login/
Traceback (most recent call last):
  File "D:\python_env\dssms_env_for_win\lib\site-packages\django\core\handlers\base.py", line 158, in get_response
    % (callback.__module__, view_name))
ValueError: The view company.views.do_login didn't return an HttpResponse object. It returned None instead.
2017-02-28 23:44:52,207 [Thread-7:760] [django.request:284] [base:handle_uncaught_exception] [ERROR]- Internal Server Error: /login/
Traceback (most recent call last):
  File "D:\python_env\dssms_env_for_win\lib\site-packages\django\core\handlers\base.py", line 149, in get_response
    response = self.process_exception_by_middleware(e, request)
  File "D:\python_env\dssms_env_for_win\lib\site-packages\django\core\handlers\base.py", line 147, in get_response
    response = wrapped_callback(request, *callback_args, **callback_kwargs)
  File "D:/python_env/dssms_project\company\views.py", line 124, in do_login
    user = authenticate(organization__company_name=companyname, username=username, password=password)
  File "D:\python_env\dssms_env_for_win\lib\site-packages\django\contrib\auth\__init__.py", line 74, in authenticate
    user = backend.authenticate(**credentials)
  File "D:\python_env\dssms_env_for_win\lib\site-packages\django\contrib\auth\backends.py", line 17, in authenticate
    user = UserModel._default_manager.get_by_natural_key(username)
  File "D:\python_env\dssms_env_for_win\lib\site-packages\django\contrib\auth\base_user.py", line 45, in get_by_natural_key
    return self.get(**{self.model.USERNAME_FIELD: username})
  File "D:\python_env\dssms_env_for_win\lib\site-packages\django\db\models\manager.py", line 122, in manager_method
    return getattr(self.get_queryset(), name)(*args, **kwargs)
  File "D:\python_env\dssms_env_for_win\lib\site-packages\django\db\models\query.py", line 381, in get
    num = len(clone)
  File "D:\python_env\dssms_env_for_win\lib\site-packages\django\db\models\query.py", line 240, in __len__
    self._fetch_all()
  File "D:\python_env\dssms_env_for_win\lib\site-packages\django\db\models\query.py", line 1074, in _fetch_all
    self._result_cache = list(self.iterator())
  File "D:\python_env\dssms_env_for_win\lib\site-packages\django\db\models\query.py", line 52, in __iter__
    results = compiler.execute_sql()
  File "D:\python_env\dssms_env_for_win\lib\site-packages\django\db\models\sql\compiler.py", line 848, in execute_sql
    cursor.execute(sql, params)
  File "D:\python_env\dssms_env_for_win\lib\site-packages\django\db\backends\utils.py", line 79, in execute
    return super(CursorDebugWrapper, self).execute(sql, params)
  File "D:\python_env\dssms_env_for_win\lib\site-packages\django\db\backends\utils.py", line 64, in execute
    return self.cursor.execute(sql, params)
  File "D:\python_env\dssms_env_for_win\lib\site-packages\django\db\utils.py", line 95, in __exit__
    six.reraise(dj_exc_type, dj_exc_value, traceback)
  File "D:\python_env\dssms_env_for_win\lib\site-packages\django\db\backends\utils.py", line 64, in execute
    return self.cursor.execute(sql, params)
  File "D:\python_env\dssms_env_for_win\lib\site-packages\django\db\backends\sqlite3\base.py", line 323, in execute
    return Database.Cursor.execute(self, query, params)
OperationalError: no such table: company_staff
2017-03-01 00:13:42,753 [Thread-7:1124] [django.request:284] [base:handle_uncaught_exception] [ERROR]- Internal Server Error: /login/
Traceback (most recent call last):
  File "D:\python_env\dssms_env_for_win\lib\site-packages\django\core\handlers\base.py", line 158, in get_response
    % (callback.__module__, view_name))
ValueError: The view company.views.do_login didn't return an HttpResponse object. It returned None instead.
2017-03-01 00:14:27,177 [Thread-15:13288] [django.request:284] [base:handle_uncaught_exception] [ERROR]- Internal Server Error: /login/
Traceback (most recent call last):
  File "D:\python_env\dssms_env_for_win\lib\site-packages\django\core\handlers\base.py", line 158, in get_response
    % (callback.__module__, view_name))
ValueError: The view company.views.do_login didn't return an HttpResponse object. It returned None instead.
2017-03-01 00:42:38,930 [Thread-10:11368] [django.request:182] [base:get_response] [WARNING]- Not Found: /
2017-03-01 00:42:48,082 [Thread-14:1776] [django.request:284] [base:handle_uncaught_exception] [ERROR]- Internal Server Error: /login/
Traceback (most recent call last):
  File "D:\python_env\dssms_env_for_win\lib\site-packages\django\core\handlers\base.py", line 158, in get_response
    % (callback.__module__, view_name))
ValueError: The view company.views.do_login didn't return an HttpResponse object. It returned None instead.
2017-03-01 00:43:30,474 [Thread-15:11328] [django.request:284] [base:handle_uncaught_exception] [ERROR]- Internal Server Error: /login/
Traceback (most recent call last):
  File "D:\python_env\dssms_env_for_win\lib\site-packages\django\core\handlers\base.py", line 158, in get_response
    % (callback.__module__, view_name))
ValueError: The view company.views.do_login didn't return an HttpResponse object. It returned None instead.
2017-03-01 00:43:37,957 [Thread-17:9780] [django.request:284] [base:handle_uncaught_exception] [ERROR]- Internal Server Error: /login/
Traceback (most recent call last):
  File "D:\python_env\dssms_env_for_win\lib\site-packages\django\core\handlers\base.py", line 158, in get_response
    % (callback.__module__, view_name))
ValueError: The view company.views.do_login didn't return an HttpResponse object. It returned None instead.
2017-03-01 00:44:13,569 [Thread-22:7000] [django.request:182] [base:get_response] [WARNING]- Not Found: /favicon.ico
2017-03-01 00:44:20,266 [Thread-23:12280] [django.request:284] [base:handle_uncaught_exception] [ERROR]- Internal Server Error: /login/
Traceback (most recent call last):
  File "D:\python_env\dssms_env_for_win\lib\site-packages\django\core\handlers\base.py", line 158, in get_response
    % (callback.__module__, view_name))
ValueError: The view company.views.do_login didn't return an HttpResponse object. It returned None instead.
2017-03-01 00:45:09,640 [Thread-13:5640] [django.request:284] [base:handle_uncaught_exception] [ERROR]- Internal Server Error: /login/
Traceback (most recent call last):
  File "D:\python_env\dssms_env_for_win\lib\site-packages\django\core\handlers\base.py", line 158, in get_response
    % (callback.__module__, view_name))
ValueError: The view company.views.do_login didn't return an HttpResponse object. It returned None instead.
2017-03-01 23:54:45,288 [Thread-3:9456] [django.request:182] [base:get_response] [WARNING]- Not Found: /favicon.ico
2017-03-02 23:45:31,684 [Thread-18:6452] [django.request:182] [base:get_response] [WARNING]- Not Found: /favicon.ico
2017-03-02 23:45:31,730 [Thread-19:1364] [django.request:182] [base:get_response] [WARNING]- Not Found: /login/regist
2017-03-02 23:46:05,046 [Thread-2:4284] [django.request:182] [base:get_response] [WARNING]- Not Found: /login/regist
2017-03-02 23:46:05,944 [Thread-3:14108] [django.request:182] [base:get_response] [WARNING]- Not Found: /login/regist
2017-03-02 23:46:07,904 [Thread-4:8416] [django.request:182] [base:get_response] [WARNING]- Not Found: /login/regist
2017-03-02 23:46:27,551 [Thread-10:1324] [django.request:182] [base:get_response] [WARNING]- Not Found: /login/regist
2017-03-02 23:46:31,763 [Thread-11:12124] [django.request:182] [base:get_response] [WARNING]- Not Found: /login/regist
2017-03-02 23:47:03,187 [Thread-2:5220] [django.request:182] [base:get_response] [WARNING]- Not Found: /login/regist
2017-03-02 23:47:03,878 [Thread-3:10124] [django.request:182] [base:get_response] [WARNING]- Not Found: /login/regist
2017-03-02 23:47:04,040 [Thread-4:8088] [django.request:182] [base:get_response] [WARNING]- Not Found: /login/regist
2017-03-02 23:47:08,217 [Thread-5:7492] [django.request:182] [base:get_response] [WARNING]- Not Found: /login/regist
2017-03-04 01:32:54,193 [Thread-3:2656] [django.request:284] [base:handle_uncaught_exception] [ERROR]- Internal Server Error: /login/
Traceback (most recent call last):
  File "D:\python_env\dssms_env_for_win\lib\site-packages\django\core\handlers\base.py", line 149, in get_response
    response = self.process_exception_by_middleware(e, request)
  File "D:\python_env\dssms_env_for_win\lib\site-packages\django\core\handlers\base.py", line 147, in get_response
    response = wrapped_callback(request, *callback_args, **callback_kwargs)
  File "D:\python_env\dssms_env_for_win\lib\site-packages\django\views\generic\base.py", line 68, in view
    return self.dispatch(request, *args, **kwargs)
  File "D:\python_env\dssms_env_for_win\lib\site-packages\django\views\generic\base.py", line 88, in dispatch
    return handler(request, *args, **kwargs)
  File "D:\python_env\dssms_project\company\views.py", line 20, in get
    register_form = RegistForm()
NameError: global name 'RegistForm' is not defined
2017-03-04 01:32:54,961 [Thread-4:13932] [django.request:182] [base:get_response] [WARNING]- Not Found: /favicon.ico
2017-03-04 01:34:39,164 [Thread-19:13504] [django.request:182] [base:get_response] [WARNING]- Not Found: /login/regist
2017-03-04 01:35:21,640 [Thread-2:10400] [django.request:182] [base:get_response] [WARNING]- Not Found: /login/regist
2017-03-04 01:35:24,924 [Thread-3:5944] [django.request:182] [base:get_response] [WARNING]- Not Found: /login/regist
2017-03-04 01:39:02,069 [Thread-2:1452] [django.request:182] [base:get_response] [WARNING]- Not Found: /login/regist
2017-03-04 01:41:05,111 [Thread-33:5496] [django.request:182] [base:get_response] [WARNING]- Not Found: /favicon.ico
2017-03-04 01:41:36,490 [Thread-39:12392] [django.request:284] [base:handle_uncaught_exception] [ERROR]- Internal Server Error: /regist
Traceback (most recent call last):
  File "D:\python_env\dssms_env_for_win\lib\site-packages\django\core\handlers\base.py", line 158, in get_response
    % (callback.__module__, view_name))
ValueError: The view company.views.RegisterView didn't return an HttpResponse object. It returned None instead.
2017-03-05 11:32:48,588 [Thread-22:4664] [django.request:182] [base:get_response] [WARNING]- Not Found: /favicon.ico
2017-03-05 11:37:01,921 [Thread-78:11624] [django.request:103] [csrf:_reject] [WARNING]- Forbidden (CSRF token missing or incorrect.): /login/
2017-03-05 11:37:03,677 [Thread-79:12240] [django.request:103] [csrf:_reject] [WARNING]- Forbidden (CSRF token missing or incorrect.): /login/
2017-03-05 11:37:04,230 [Thread-80:3540] [django.request:103] [csrf:_reject] [WARNING]- Forbidden (CSRF token missing or incorrect.): /login/
2017-03-05 11:37:04,404 [Thread-81:8944] [django.request:103] [csrf:_reject] [WARNING]- Forbidden (CSRF token missing or incorrect.): /login/
2017-03-05 11:37:04,578 [Thread-82:10976] [django.request:103] [csrf:_reject] [WARNING]- Forbidden (CSRF token missing or incorrect.): /login/
2017-03-05 11:37:04,730 [Thread-83:744] [django.request:103] [csrf:_reject] [WARNING]- Forbidden (CSRF token missing or incorrect.): /login/
2017-03-05 11:37:04,891 [Thread-84:10468] [django.request:103] [csrf:_reject] [WARNING]- Forbidden (CSRF token missing or incorrect.): /login/
2017-03-05 11:42:09,283 [Thread-4:2972] [django.request:103] [csrf:_reject] [WARNING]- Forbidden (CSRF token missing or incorrect.): /login/
2017-03-05 11:42:11,881 [Thread-5:10784] [django.request:103] [csrf:_reject] [WARNING]- Forbidden (CSRF token missing or incorrect.): /login/
2017-03-05 11:43:39,614 [Thread-27:10200] [django.request:103] [csrf:_reject] [WARNING]- Forbidden (CSRF token missing or incorrect.): /login/
2017-03-05 11:43:58,813 [Thread-50:6260] [django.request:182] [base:get_response] [WARNING]- Not Found: /login/img/a5.jpg
2017-03-05 11:43:58,813 [Thread-51:9588] [django.request:182] [base:get_response] [WARNING]- Not Found: /login/img/a2.jpg
2017-03-05 11:43:58,813 [Thread-49:11064] [django.request:182] [base:get_response] [WARNING]- Not Found: /login/img/c0.jpg
2017-03-05 11:43:58,815 [Thread-52:11404] [django.request:182] [base:get_response] [WARNING]- Not Found: /login/img/a4.jpg
2017-03-05 11:43:58,815 [Thread-53:6796] [django.request:182] [base:get_response] [WARNING]- Not Found: /login/img/a8.jpg
2017-03-05 11:43:58,816 [Thread-54:4216] [django.request:182] [base:get_response] [WARNING]- Not Found: /login/img/a3.jpg
2017-03-05 11:43:58,874 [Thread-55:6460] [django.request:182] [base:get_response] [WARNING]- Not Found: /login/img/a1.jpg
2017-03-05 11:43:58,878 [Thread-56:8860] [django.request:182] [base:get_response] [WARNING]- Not Found: /login/img/a9.jpg
2017-03-05 11:43:58,881 [Thread-57:9788] [django.request:182] [base:get_response] [WARNING]- Not Found: /login/img/a6.jpg
2017-03-05 11:43:58,884 [Thread-58:7532] [django.request:182] [base:get_response] [WARNING]- Not Found: /login/img/a7.jpg
2017-03-05 11:43:58,884 [Thread-59:8936] [django.request:182] [base:get_response] [WARNING]- Not Found: /login/img/a10.jpg
2017-03-05 11:51:15,822 [Thread-66:9048] [django.request:103] [csrf:_reject] [WARNING]- Forbidden (CSRF token missing or incorrect.): /login/
2017-03-05 11:52:30,877 [Thread-82:12964] [django.request:182] [base:get_response] [WARNING]- Not Found: /login/img/c0.jpg
2017-03-05 11:52:30,877 [Thread-83:3632] [django.request:182] [base:get_response] [WARNING]- Not Found: /login/img/a5.jpg
2017-03-05 11:52:30,877 [Thread-84:11656] [django.request:182] [base:get_response] [WARNING]- Not Found: /login/img/a2.jpg
2017-03-05 11:52:30,878 [Thread-86:10652] [django.request:182] [base:get_response] [WARNING]- Not Found: /login/img/a8.jpg
2017-03-05 11:52:30,877 [Thread-85:11364] [django.request:182] [base:get_response] [WARNING]- Not Found: /login/img/a4.jpg
2017-03-05 11:52:30,878 [Thread-87:13524] [django.request:182] [base:get_response] [WARNING]- Not Found: /login/img/a3.jpg
2017-03-05 11:52:30,927 [Thread-88:9360] [django.request:182] [base:get_response] [WARNING]- Not Found: /login/img/a1.jpg
2017-03-05 11:52:30,928 [Thread-89:12992] [django.request:182] [base:get_response] [WARNING]- Not Found: /login/img/a9.jpg
2017-03-05 11:52:30,930 [Thread-90:10352] [django.request:182] [base:get_response] [WARNING]- Not Found: /login/img/a6.jpg
2017-03-05 11:52:30,931 [Thread-91:400] [django.request:182] [base:get_response] [WARNING]- Not Found: /login/img/a7.jpg
2017-03-05 11:52:30,944 [Thread-92:4620] [django.request:182] [base:get_response] [WARNING]- Not Found: /login/img/a10.jpg
2017-03-05 11:52:51,687 [Thread-94:888] [django.request:182] [base:get_response] [WARNING]- Not Found: /login/img/a1.jpg
2017-03-05 11:52:51,693 [Thread-97:3960] [django.request:182] [base:get_response] [WARNING]- Not Found: /login/img/a4.jpg
2017-03-05 11:52:51,694 [Thread-95:9892] [django.request:182] [base:get_response] [WARNING]- Not Found: /login/img/a2.jpg
2017-03-05 11:52:51,694 [Thread-96:10828] [django.request:182] [base:get_response] [WARNING]- Not Found: /login/img/a3.jpg
2017-03-05 11:52:51,694 [Thread-98:9916] [django.request:182] [base:get_response] [WARNING]- Not Found: /login/img/a5.jpg
2017-03-05 11:52:51,696 [Thread-99:8644] [django.request:182] [base:get_response] [WARNING]- Not Found: /login/img/a6.jpg
2017-03-05 11:52:51,742 [Thread-100:7348] [django.request:182] [base:get_response] [WARNING]- Not Found: /login/img/a7.jpg
2017-03-05 11:52:51,746 [Thread-101:7260] [django.request:182] [base:get_response] [WARNING]- Not Found: /login/img/a8.jpg
2017-03-05 11:53:40,523 [Thread-107:4616] [django.request:103] [csrf:_reject] [WARNING]- Forbidden (CSRF token missing or incorrect.): /login/
2017-03-05 11:53:41,313 [Thread-108:6828] [django.request:103] [csrf:_reject] [WARNING]- Forbidden (CSRF token missing or incorrect.): /login/
2017-03-05 11:53:41,477 [Thread-109:13060] [django.request:103] [csrf:_reject] [WARNING]- Forbidden (CSRF token missing or incorrect.): /login/
2017-03-05 11:53:41,631 [Thread-110:720] [django.request:103] [csrf:_reject] [WARNING]- Forbidden (CSRF token missing or incorrect.): /login/
2017-03-05 11:57:10,546 [Thread-122:5680] [django.request:103] [csrf:_reject] [WARNING]- Forbidden (CSRF token missing or incorrect.): /login/
2017-03-05 11:57:13,295 [Thread-123:8104] [django.request:103] [csrf:_reject] [WARNING]- Forbidden (CSRF token missing or incorrect.): /login/
2017-03-05 11:58:33,681 [Thread-131:10508] [django.request:103] [csrf:_reject] [WARNING]- Forbidden (CSRF token missing or incorrect.): /login/
2017-03-05 11:58:51,976 [Thread-139:8544] [django.request:182] [base:get_response] [WARNING]- Not Found: /login/img/a1.jpg
2017-03-05 11:58:51,976 [Thread-140:228] [django.request:182] [base:get_response] [WARNING]- Not Found: /login/img/a2.jpg
2017-03-05 11:58:51,976 [Thread-142:280] [django.request:182] [base:get_response] [WARNING]- Not Found: /login/img/a4.jpg
2017-03-05 11:58:51,976 [Thread-141:744] [django.request:182] [base:get_response] [WARNING]- Not Found: /login/img/a3.jpg
2017-03-05 11:58:51,976 [Thread-143:9048] [django.request:182] [base:get_response] [WARNING]- Not Found: /login/img/a5.jpg
2017-03-05 11:58:51,976 [Thread-144:6348] [django.request:182] [base:get_response] [WARNING]- Not Found: /login/img/a6.jpg
2017-03-05 11:58:52,022 [Thread-145:7520] [django.request:182] [base:get_response] [WARNING]- Not Found: /login/img/a7.jpg
2017-03-05 11:58:52,022 [Thread-146:8064] [django.request:182] [base:get_response] [WARNING]- Not Found: /login/img/a8.jpg
2017-03-05 12:26:09,594 [Thread-16:7496] [django.request:182] [base:get_response] [WARNING]- Not Found: /login/img/a0.jpg
2017-03-05 12:26:09,596 [Thread-17:11776] [django.request:182] [base:get_response] [WARNING]- Not Found: /login/img/a1.jpg
2017-03-05 12:26:09,598 [Thread-18:12276] [django.request:182] [base:get_response] [WARNING]- Not Found: /login/img/a2.jpg
2017-03-05 12:26:09,598 [Thread-19:10720] [django.request:182] [base:get_response] [WARNING]- Not Found: /login/img/a3.jpg
2017-03-05 12:26:09,599 [Thread-20:9144] [django.request:182] [base:get_response] [WARNING]- Not Found: /login/img/a4.jpg
2017-03-05 12:26:11,331 [Thread-22:10628] [django.request:182] [base:get_response] [WARNING]- Not Found: /login/img/a0.jpg
2017-03-05 12:26:11,332 [Thread-23:11904] [django.request:182] [base:get_response] [WARNING]- Not Found: /login/img/a9.jpg
2017-03-05 12:26:11,332 [Thread-24:8364] [django.request:182] [base:get_response] [WARNING]- Not Found: /login/img/a5.jpg
2017-03-05 12:26:11,332 [Thread-26:2964] [django.request:182] [base:get_response] [WARNING]- Not Found: /login/img/a6.jpg
2017-03-05 12:26:11,332 [Thread-25:6628] [django.request:182] [base:get_response] [WARNING]- Not Found: /login/img/a3.jpg
2017-03-05 12:26:11,332 [Thread-27:9364] [django.request:182] [base:get_response] [WARNING]- Not Found: /login/img/c5.jpg
2017-03-05 12:26:11,382 [Thread-28:11004] [django.request:182] [base:get_response] [WARNING]- Not Found: /login/img/a7.jpg
2017-03-05 12:26:11,384 [Thread-29:3456] [django.request:182] [base:get_response] [WARNING]- Not Found: /login/img/c4.jpg
2017-03-05 12:26:11,384 [Thread-30:12004] [django.request:182] [base:get_response] [WARNING]- Not Found: /login/img/a4.jpg
2017-03-05 12:26:11,385 [Thread-31:11804] [django.request:182] [base:get_response] [WARNING]- Not Found: /login/img/a2.jpg
2017-03-05 12:26:12,069 [Thread-33:7424] [django.request:182] [base:get_response] [WARNING]- Not Found: /login/img/c0.jpg
2017-03-05 12:26:12,071 [Thread-34:10536] [django.request:182] [base:get_response] [WARNING]- Not Found: /login/img/a0.jpg
2017-03-05 12:26:12,071 [Thread-35:3540] [django.request:182] [base:get_response] [WARNING]- Not Found: /login/img/a1.jpg
2017-03-05 12:26:12,071 [Thread-36:13976] [django.request:182] [base:get_response] [WARNING]- Not Found: /login/img/a2.jpg
2017-03-05 12:26:12,071 [Thread-37:10848] [django.request:182] [base:get_response] [WARNING]- Not Found: /login/img/b0.jpg
2017-03-05 12:26:12,071 [Thread-38:9704] [django.request:182] [base:get_response] [WARNING]- Not Found: /login/img/b1.jpg
2017-03-05 12:26:12,112 [Thread-39:9680] [django.request:182] [base:get_response] [WARNING]- Not Found: /login/img/b2.jpg
2017-03-05 12:26:16,193 [Thread-43:8460] [django.request:182] [base:get_response] [WARNING]- Not Found: /login/css/bootstrap.css
2017-03-05 12:26:16,197 [Thread-44:5156] [django.request:182] [base:get_response] [WARNING]- Not Found: /login/css/animate.css
2017-03-05 12:26:16,198 [Thread-45:12144] [django.request:182] [base:get_response] [WARNING]- Not Found: /login/css/font-awesome.min.css
2017-03-05 12:26:16,200 [Thread-46:9172] [django.request:182] [base:get_response] [WARNING]- Not Found: /login/css/simple-line-icons.css
2017-03-05 12:26:16,203 [Thread-47:8264] [django.request:182] [base:get_response] [WARNING]- Not Found: /login/css/font.css
2017-03-05 12:26:16,204 [Thread-48:10212] [django.request:182] [base:get_response] [WARNING]- Not Found: /login/css/app.css
2017-03-05 12:26:16,207 [Thread-49:13228] [django.request:182] [base:get_response] [WARNING]- Not Found: /login/js/jquery.min.js
2017-03-05 12:26:16,255 [Thread-50:11136] [django.request:182] [base:get_response] [WARNING]- Not Found: /login/img/a0.jpg
2017-03-05 12:26:21,809 [Thread-51:7844] [django.request:103] [csrf:_reject] [WARNING]- Forbidden (CSRF token missing or incorrect.): /login/
2017-03-05 12:30:31,391 [Thread-83:13912] [django.request:182] [base:get_response] [WARNING]- Not Found: /login/img/c0.jpg
2017-03-05 12:30:31,391 [Thread-86:5776] [django.request:182] [base:get_response] [WARNING]- Not Found: /login/img/a4.jpg
2017-03-05 12:30:31,391 [Thread-85:4216] [django.request:182] [base:get_response] [WARNING]- Not Found: /login/img/a2.jpg
2017-03-05 12:30:31,391 [Thread-84:13128] [django.request:182] [base:get_response] [WARNING]- Not Found: /login/img/a5.jpg
2017-03-05 12:30:31,391 [Thread-87:3148] [django.request:182] [base:get_response] [WARNING]- Not Found: /login/img/a8.jpg
2017-03-05 12:30:31,392 [Thread-88:3744] [django.request:182] [base:get_response] [WARNING]- Not Found: /login/img/a3.jpg
2017-03-05 12:30:31,447 [Thread-89:856] [django.request:182] [base:get_response] [WARNING]- Not Found: /login/img/a1.jpg
2017-03-05 12:30:31,448 [Thread-90:6776] [django.request:182] [base:get_response] [WARNING]- Not Found: /login/img/a9.jpg
2017-03-05 12:30:31,451 [Thread-91:5940] [django.request:182] [base:get_response] [WARNING]- Not Found: /login/img/a6.jpg
2017-03-05 12:30:31,454 [Thread-92:11880] [django.request:182] [base:get_response] [WARNING]- Not Found: /login/img/a7.jpg
2017-03-05 12:30:31,457 [Thread-93:10944] [django.request:182] [base:get_response] [WARNING]- Not Found: /login/img/a10.jpg
2017-03-05 12:30:42,967 [Thread-100:11772] [django.request:182] [base:get_response] [WARNING]- Not Found: /login/img/c0.jpg
2017-03-05 12:30:42,967 [Thread-101:196] [django.request:182] [base:get_response] [WARNING]- Not Found: /login/img/a5.jpg
2017-03-05 12:30:42,967 [Thread-102:10172] [django.request:182] [base:get_response] [WARNING]- Not Found: /login/img/a2.jpg
2017-03-05 12:30:42,967 [Thread-103:2608] [django.request:182] [base:get_response] [WARNING]- Not Found: /login/img/a4.jpg
2017-03-05 12:30:42,967 [Thread-105:13832] [django.request:182] [base:get_response] [WARNING]- Not Found: /login/img/a3.jpg
2017-03-05 12:30:42,967 [Thread-104:4196] [django.request:182] [base:get_response] [WARNING]- Not Found: /login/img/a8.jpg
2017-03-05 12:30:43,016 [Thread-106:12592] [django.request:182] [base:get_response] [WARNING]- Not Found: /login/img/a1.jpg
2017-03-05 12:30:43,019 [Thread-107:7464] [django.request:182] [base:get_response] [WARNING]- Not Found: /login/img/a9.jpg
2017-03-05 12:30:43,022 [Thread-108:14064] [django.request:182] [base:get_response] [WARNING]- Not Found: /login/img/a6.jpg
2017-03-05 12:30:43,026 [Thread-109:13316] [django.request:182] [base:get_response] [WARNING]- Not Found: /login/img/a7.jpg
2017-03-05 12:30:43,029 [Thread-110:10692] [django.request:182] [base:get_response] [WARNING]- Not Found: /login/img/a10.jpg
2017-03-05 12:30:45,329 [Thread-113:12380] [django.request:182] [base:get_response] [WARNING]- Not Found: /login/img/a1.jpg
2017-03-05 12:30:45,329 [Thread-114:14296] [django.request:182] [base:get_response] [WARNING]- Not Found: /login/img/a2.jpg
2017-03-05 12:30:45,331 [Thread-115:11484] [django.request:182] [base:get_response] [WARNING]- Not Found: /login/img/a3.jpg
2017-03-05 12:30:45,331 [Thread-116:11356] [django.request:182] [base:get_response] [WARNING]- Not Found: /login/img/a4.jpg
2017-03-05 12:30:46,045 [Thread-119:9112] [django.request:182] [base:get_response] [WARNING]- Not Found: /login/img/a7.jpg
2017-03-05 12:30:46,046 [Thread-118:4464] [django.request:182] [base:get_response] [WARNING]- Not Found: /login/img/a4.jpg
2017-03-05 12:30:46,046 [Thread-120:2528] [django.request:182] [base:get_response] [WARNING]- Not Found: /login/img/a8.jpg
2017-03-05 12:30:46,046 [Thread-121:12764] [django.request:182] [base:get_response] [WARNING]- Not Found: /login/img/a9.jpg
2017-03-05 12:30:46,048 [Thread-122:3836] [django.request:182] [base:get_response] [WARNING]- Not Found: /login/img/a10.jpg
2017-03-08 00:15:22,696 [Thread-2:140027258898176] [django.request:182] [base:get_response] [WARNING]- Not Found: /
2017-03-08 00:15:22,922 [Thread-3:140027258898176] [django.request:182] [base:get_response] [WARNING]- Not Found: /favicon.ico
2017-03-08 00:15:22,981 [Thread-4:140027258898176] [django.request:182] [base:get_response] [WARNING]- Not Found: /favicon.ico
2017-03-08 00:22:58,615 [Thread-90:140027233720064] [django.request:182] [base:get_response] [WARNING]- Not Found: /login/img/a1.jpg
2017-03-08 00:22:58,628 [Thread-91:140027233720064] [django.request:182] [base:get_response] [WARNING]- Not Found: /login/img/a2.jpg
2017-03-08 00:22:58,641 [Thread-93:140027242112768] [django.request:182] [base:get_response] [WARNING]- Not Found: /login/img/a4.jpg
2017-03-08 00:22:58,642 [Thread-92:140027233720064] [django.request:182] [base:get_response] [WARNING]- Not Found: /login/img/a3.jpg
2017-03-08 00:22:58,653 [Thread-94:140027250505472] [django.request:182] [base:get_response] [WARNING]- Not Found: /login/img/a5.jpg
2017-03-08 00:22:58,669 [Thread-95:140027233720064] [django.request:182] [base:get_response] [WARNING]- Not Found: /login/img/a6.jpg
2017-03-08 00:22:58,692 [Thread-96:140027225327360] [django.request:182] [base:get_response] [WARNING]- Not Found: /login/img/a7.jpg
2017-03-08 00:22:58,726 [Thread-97:140027250505472] [django.request:182] [base:get_response] [WARNING]- Not Found: /login/img/a8.jpg
2017-03-08 23:19:23,874 [Thread-2:140412789737216] [django.request:182] [base:get_response] [WARNING]- Not Found: /
2017-03-08 23:19:27,707 [Thread-3:140412789737216] [django.request:182] [base:get_response] [WARNING]- Not Found: /favicon.ico
2017-03-08 23:33:57,944 [Thread-7:139918810973952] [django.request:103] [csrf:_reject] [WARNING]- Forbidden (CSRF token missing or incorrect.): /login/
2017-03-09 02:33:34,884 [Thread-2:123145389137920] [django.request:182] [base:get_response] [WARNING]- Not Found: /
2017-03-09 02:33:39,588 [Thread-3:123145388601344] [django.request:182] [base:get_response] [WARNING]- Not Found: /
2017-03-09 09:42:37,602 [Thread-6:123145566162944] [django.request:182] [base:get_response] [WARNING]- Not Found: /favicon.ico
2017-03-09 09:45:07,451 [Thread-10:123145549336576] [django.request:103] [csrf:_reject] [WARNING]- Forbidden (CSRF token missing or incorrect.): /login/
2017-03-09 10:00:12,259 [Thread-8:123145514020864] [django.request:284] [base:handle_uncaught_exception] [ERROR]- Internal Server Error: /regist
Traceback (most recent call last):
  File "/Users/user/project_env/dssms_env/lib/python2.7/site-packages/django/core/handlers/base.py", line 149, in get_response
    response = self.process_exception_by_middleware(e, request)
  File "/Users/user/project_env/dssms_env/lib/python2.7/site-packages/django/core/handlers/base.py", line 147, in get_response
    response = wrapped_callback(request, *callback_args, **callback_kwargs)
  File "/Users/user/project_env/dssms_env/lib/python2.7/site-packages/django/views/generic/base.py", line 68, in view
    return self.dispatch(request, *args, **kwargs)
  File "/Users/user/project_env/dssms_env/lib/python2.7/site-packages/django/views/generic/base.py", line 88, in dispatch
    return handler(request, *args, **kwargs)
  File "/Users/user/workspace/Python/web/dssms_project/company/views.py", line 78, in post
    department.save()
  File "/Users/user/project_env/dssms_env/lib/python2.7/site-packages/django/db/models/base.py", line 708, in save
    force_update=force_update, update_fields=update_fields)
  File "/Users/user/project_env/dssms_env/lib/python2.7/site-packages/django/db/models/base.py", line 736, in save_base
    updated = self._save_table(raw, cls, force_insert, force_update, using, update_fields)
  File "/Users/user/project_env/dssms_env/lib/python2.7/site-packages/django/db/models/base.py", line 820, in _save_table
    result = self._do_insert(cls._base_manager, using, fields, update_pk, raw)
  File "/Users/user/project_env/dssms_env/lib/python2.7/site-packages/django/db/models/base.py", line 859, in _do_insert
    using=using, raw=raw)
  File "/Users/user/project_env/dssms_env/lib/python2.7/site-packages/django/db/models/manager.py", line 122, in manager_method
    return getattr(self.get_queryset(), name)(*args, **kwargs)
  File "/Users/user/project_env/dssms_env/lib/python2.7/site-packages/django/db/models/query.py", line 1039, in _insert
    return query.get_compiler(using=using).execute_sql(return_id)
  File "/Users/user/project_env/dssms_env/lib/python2.7/site-packages/django/db/models/sql/compiler.py", line 1060, in execute_sql
    cursor.execute(sql, params)
  File "/Users/user/project_env/dssms_env/lib/python2.7/site-packages/django/db/backends/utils.py", line 79, in execute
    return super(CursorDebugWrapper, self).execute(sql, params)
  File "/Users/user/project_env/dssms_env/lib/python2.7/site-packages/django/db/backends/utils.py", line 64, in execute
    return self.cursor.execute(sql, params)
  File "/Users/user/project_env/dssms_env/lib/python2.7/site-packages/django/db/utils.py", line 95, in __exit__
    six.reraise(dj_exc_type, dj_exc_value, traceback)
  File "/Users/user/project_env/dssms_env/lib/python2.7/site-packages/django/db/backends/utils.py", line 64, in execute
    return self.cursor.execute(sql, params)
  File "/Users/user/project_env/dssms_env/lib/python2.7/site-packages/django/db/backends/sqlite3/base.py", line 323, in execute
    return Database.Cursor.execute(self, query, params)
IntegrityError: NOT NULL constraint failed: company_department.duty_id
2017-03-09 10:05:57,985 [Thread-11:123145546207232] [django.request:284] [base:handle_uncaught_exception] [ERROR]- Internal Server Error: /login/
Traceback (most recent call last):
  File "/Users/user/project_env/dssms_env/lib/python2.7/site-packages/django/core/handlers/base.py", line 149, in get_response
    response = self.process_exception_by_middleware(e, request)
  File "/Users/user/project_env/dssms_env/lib/python2.7/site-packages/django/core/handlers/base.py", line 147, in get_response
    response = wrapped_callback(request, *callback_args, **callback_kwargs)
  File "/Users/user/project_env/dssms_env/lib/python2.7/site-packages/django/views/generic/base.py", line 68, in view
    return self.dispatch(request, *args, **kwargs)
  File "/Users/user/project_env/dssms_env/lib/python2.7/site-packages/django/views/generic/base.py", line 88, in dispatch
    return handler(request, *args, **kwargs)
  File "/Users/user/workspace/Python/web/dssms_project/company/views.py", line 29, in post
    user = authenticate(organization__company_name=companyname, username=username, password=password)
  File "/Users/user/project_env/dssms_env/lib/python2.7/site-packages/django/contrib/auth/__init__.py", line 74, in authenticate
    user = backend.authenticate(**credentials)
  File "/Users/user/project_env/dssms_env/lib/python2.7/site-packages/django/contrib/auth/backends.py", line 17, in authenticate
    user = UserModel._default_manager.get_by_natural_key(username)
  File "/Users/user/project_env/dssms_env/lib/python2.7/site-packages/django/contrib/auth/base_user.py", line 45, in get_by_natural_key
    return self.get(**{self.model.USERNAME_FIELD: username})
  File "/Users/user/project_env/dssms_env/lib/python2.7/site-packages/django/db/models/manager.py", line 122, in manager_method
    return getattr(self.get_queryset(), name)(*args, **kwargs)
  File "/Users/user/project_env/dssms_env/lib/python2.7/site-packages/django/db/models/query.py", line 381, in get
    num = len(clone)
  File "/Users/user/project_env/dssms_env/lib/python2.7/site-packages/django/db/models/query.py", line 240, in __len__
    self._fetch_all()
  File "/Users/user/project_env/dssms_env/lib/python2.7/site-packages/django/db/models/query.py", line 1074, in _fetch_all
    self._result_cache = list(self.iterator())
  File "/Users/user/project_env/dssms_env/lib/python2.7/site-packages/django/db/models/query.py", line 52, in __iter__
    results = compiler.execute_sql()
  File "/Users/user/project_env/dssms_env/lib/python2.7/site-packages/django/db/models/sql/compiler.py", line 848, in execute_sql
    cursor.execute(sql, params)
  File "/Users/user/project_env/dssms_env/lib/python2.7/site-packages/django/db/backends/utils.py", line 79, in execute
    return super(CursorDebugWrapper, self).execute(sql, params)
  File "/Users/user/project_env/dssms_env/lib/python2.7/site-packages/django/db/backends/utils.py", line 64, in execute
    return self.cursor.execute(sql, params)
  File "/Users/user/project_env/dssms_env/lib/python2.7/site-packages/django/db/utils.py", line 95, in __exit__
    six.reraise(dj_exc_type, dj_exc_value, traceback)
  File "/Users/user/project_env/dssms_env/lib/python2.7/site-packages/django/db/backends/utils.py", line 64, in execute
    return self.cursor.execute(sql, params)
  File "/Users/user/project_env/dssms_env/lib/python2.7/site-packages/django/db/backends/sqlite3/base.py", line 323, in execute
    return Database.Cursor.execute(self, query, params)
OperationalError: no such column: company_staff.duty_id
2017-03-09 10:06:12,409 [Thread-35:123145542000640] [django.request:284] [base:handle_uncaught_exception] [ERROR]- Internal Server Error: /xadmin/
Traceback (most recent call last):
  File "/Users/user/project_env/dssms_env/lib/python2.7/site-packages/django/core/handlers/base.py", line 149, in get_response
    response = self.process_exception_by_middleware(e, request)
  File "/Users/user/project_env/dssms_env/lib/python2.7/site-packages/django/core/handlers/base.py", line 147, in get_response
    response = wrapped_callback(request, *callback_args, **callback_kwargs)
  File "/Users/user/project_env/dssms_env/lib/python2.7/site-packages/xadmin/sites.py", line 292, in wrapper
    return self.admin_view(view, cacheable)(*args, **kwargs)
  File "/Users/user/project_env/dssms_env/lib/python2.7/site-packages/django/views/decorators/cache.py", line 57, in _wrapped_view_func
    response = view_func(request, *args, **kwargs)
  File "/Users/user/project_env/dssms_env/lib/python2.7/site-packages/xadmin/sites.py", line 199, in inner
    return self.create_admin_view(self.login_view)(request, *args, **kwargs)
  File "/Users/user/project_env/dssms_env/lib/python2.7/site-packages/xadmin/views/base.py", line 256, in view
    return handler(request, *args, **kwargs)
  File "/Users/user/project_env/dssms_env/lib/python2.7/site-packages/django/views/decorators/cache.py", line 57, in _wrapped_view_func
    response = view_func(request, *args, **kwargs)
  File "/Users/user/project_env/dssms_env/lib/python2.7/site-packages/xadmin/views/website.py", line 69, in post
    return self.get(request)
  File "/Users/user/project_env/dssms_env/lib/python2.7/site-packages/django/views/decorators/cache.py", line 57, in _wrapped_view_func
    response = view_func(request, *args, **kwargs)
  File "/Users/user/project_env/dssms_env/lib/python2.7/site-packages/xadmin/views/website.py", line 65, in get
    return login(request, **defaults)
  File "/Users/user/project_env/dssms_env/lib/python2.7/site-packages/django/contrib/auth/views.py", line 49, in inner
    return func(*args, **kwargs)
  File "/Users/user/project_env/dssms_env/lib/python2.7/site-packages/django/views/decorators/debug.py", line 76, in sensitive_post_parameters_wrapper
    return view(request, *args, **kwargs)
  File "/Users/user/project_env/dssms_env/lib/python2.7/site-packages/django/utils/decorators.py", line 149, in _wrapped_view
    response = view_func(request, *args, **kwargs)
  File "/Users/user/project_env/dssms_env/lib/python2.7/site-packages/django/views/decorators/cache.py", line 57, in _wrapped_view_func
    response = view_func(request, *args, **kwargs)
  File "/Users/user/project_env/dssms_env/lib/python2.7/site-packages/django/contrib/auth/views.py", line 69, in login
    if form.is_valid():
  File "/Users/user/project_env/dssms_env/lib/python2.7/site-packages/django/forms/forms.py", line 161, in is_valid
    return self.is_bound and not self.errors
  File "/Users/user/project_env/dssms_env/lib/python2.7/site-packages/django/forms/forms.py", line 153, in errors
    self.full_clean()
  File "/Users/user/project_env/dssms_env/lib/python2.7/site-packages/django/forms/forms.py", line 363, in full_clean
    self._clean_form()
  File "/Users/user/project_env/dssms_env/lib/python2.7/site-packages/django/forms/forms.py", line 390, in _clean_form
    cleaned_data = self.clean()
  File "/Users/user/project_env/dssms_env/lib/python2.7/site-packages/xadmin/forms.py", line 30, in clean
    username=username, password=password)
  File "/Users/user/project_env/dssms_env/lib/python2.7/site-packages/django/contrib/auth/__init__.py", line 74, in authenticate
    user = backend.authenticate(**credentials)
  File "/Users/user/project_env/dssms_env/lib/python2.7/site-packages/django/contrib/auth/backends.py", line 17, in authenticate
    user = UserModel._default_manager.get_by_natural_key(username)
  File "/Users/user/project_env/dssms_env/lib/python2.7/site-packages/django/contrib/auth/base_user.py", line 45, in get_by_natural_key
    return self.get(**{self.model.USERNAME_FIELD: username})
  File "/Users/user/project_env/dssms_env/lib/python2.7/site-packages/django/db/models/manager.py", line 122, in manager_method
    return getattr(self.get_queryset(), name)(*args, **kwargs)
  File "/Users/user/project_env/dssms_env/lib/python2.7/site-packages/django/db/models/query.py", line 381, in get
    num = len(clone)
  File "/Users/user/project_env/dssms_env/lib/python2.7/site-packages/django/db/models/query.py", line 240, in __len__
    self._fetch_all()
  File "/Users/user/project_env/dssms_env/lib/python2.7/site-packages/django/db/models/query.py", line 1074, in _fetch_all
    self._result_cache = list(self.iterator())
  File "/Users/user/project_env/dssms_env/lib/python2.7/site-packages/django/db/models/query.py", line 52, in __iter__
    results = compiler.execute_sql()
  File "/Users/user/project_env/dssms_env/lib/python2.7/site-packages/django/db/models/sql/compiler.py", line 848, in execute_sql
    cursor.execute(sql, params)
  File "/Users/user/project_env/dssms_env/lib/python2.7/site-packages/django/db/backends/utils.py", line 79, in execute
    return super(CursorDebugWrapper, self).execute(sql, params)
  File "/Users/user/project_env/dssms_env/lib/python2.7/site-packages/django/db/backends/utils.py", line 64, in execute
    return self.cursor.execute(sql, params)
  File "/Users/user/project_env/dssms_env/lib/python2.7/site-packages/django/db/utils.py", line 95, in __exit__
    six.reraise(dj_exc_type, dj_exc_value, traceback)
  File "/Users/user/project_env/dssms_env/lib/python2.7/site-packages/django/db/backends/utils.py", line 64, in execute
    return self.cursor.execute(sql, params)
  File "/Users/user/project_env/dssms_env/lib/python2.7/site-packages/django/db/backends/sqlite3/base.py", line 323, in execute
    return Database.Cursor.execute(self, query, params)
OperationalError: no such column: company_staff.duty_id
2017-03-09 10:12:39,066 [Thread-17:123145391710208] [django.request:182] [base:get_response] [WARNING]- Not Found: /login/img/a7.jpg
2017-03-09 10:12:39,066 [Thread-16:123145387503616] [django.request:182] [base:get_response] [WARNING]- Not Found: /login/img/a4.jpg
2017-03-09 10:12:39,068 [Thread-18:123145395916800] [django.request:182] [base:get_response] [WARNING]- Not Found: /login/img/a8.jpg
2017-03-09 10:12:39,070 [Thread-19:123145400123392] [django.request:182] [base:get_response] [WARNING]- Not Found: /login/img/a9.jpg
2017-03-09 10:12:39,082 [Thread-20:123145404329984] [django.request:182] [base:get_response] [WARNING]- Not Found: /login/img/a10.jpg
2017-03-09 10:12:39,722 [Thread-22:123145387503616] [django.request:182] [base:get_response] [WARNING]- Not Found: /login/img/a1.jpg
2017-03-09 10:12:39,731 [Thread-23:123145391710208] [django.request:182] [base:get_response] [WARNING]- Not Found: /login/img/a2.jpg
2017-03-09 10:12:39,741 [Thread-24:123145395916800] [django.request:182] [base:get_response] [WARNING]- Not Found: /login/img/a3.jpg
2017-03-09 10:12:39,749 [Thread-25:123145400123392] [django.request:182] [base:get_response] [WARNING]- Not Found: /login/img/a4.jpg
2017-03-09 10:12:45,424 [Thread-28:123145387503616] [django.request:182] [base:get_response] [WARNING]- Not Found: /login/img/c0.jpg
2017-03-09 10:12:45,440 [Thread-29:123145391710208] [django.request:182] [base:get_response] [WARNING]- Not Found: /login/img/a5.jpg
2017-03-09 10:12:45,442 [Thread-30:123145395916800] [django.request:182] [base:get_response] [WARNING]- Not Found: /login/img/a2.jpg
2017-03-09 10:12:45,444 [Thread-31:123145387503616] [django.request:182] [base:get_response] [WARNING]- Not Found: /login/img/a4.jpg
2017-03-09 10:12:45,492 [Thread-32:123145400123392] [django.request:182] [base:get_response] [WARNING]- Not Found: /login/img/a8.jpg
2017-03-09 10:12:45,494 [Thread-33:123145404329984] [django.request:182] [base:get_response] [WARNING]- Not Found: /login/img/a3.jpg
2017-03-09 10:12:45,502 [Thread-34:123145408536576] [django.request:182] [base:get_response] [WARNING]- Not Found: /login/img/a1.jpg
2017-03-09 10:12:45,627 [Thread-35:123145387503616] [django.request:182] [base:get_response] [WARNING]- Not Found: /login/img/a9.jpg
2017-03-09 10:12:45,629 [Thread-36:123145391710208] [django.request:182] [base:get_response] [WARNING]- Not Found: /login/img/a6.jpg
2017-03-09 10:12:45,641 [Thread-37:123145395916800] [django.request:182] [base:get_response] [WARNING]- Not Found: /login/img/a7.jpg
2017-03-09 10:12:45,661 [Thread-38:123145400123392] [django.request:182] [base:get_response] [WARNING]- Not Found: /login/img/a10.jpg
2017-03-09 14:41:06,638 [Thread-8:123145550901248] [django.request:103] [csrf:_reject] [WARNING]- Forbidden (CSRF token missing or incorrect.): /login/
2017-03-09 15:04:48,814 [Thread-2:123145389813760] [django.request:284] [base:handle_uncaught_exception] [ERROR]- Internal Server Error: /index/add_staffs
Traceback (most recent call last):
  File "/Users/user/project_env/dssms_env/lib/python2.7/site-packages/django/core/handlers/base.py", line 149, in get_response
    response = self.process_exception_by_middleware(e, request)
  File "/Users/user/project_env/dssms_env/lib/python2.7/site-packages/django/core/handlers/base.py", line 147, in get_response
    response = wrapped_callback(request, *callback_args, **callback_kwargs)
  File "/Users/user/project_env/dssms_env/lib/python2.7/site-packages/django/views/generic/base.py", line 68, in view
    return self.dispatch(request, *args, **kwargs)
  File "/Users/user/project_env/dssms_env/lib/python2.7/site-packages/django/views/generic/base.py", line 88, in dispatch
    return handler(request, *args, **kwargs)
  File "/Users/user/workspace/Python/web/dssms_project/company/views.py", line 134, in get
    companyname = request.Session['companyname']
AttributeError: 'WSGIRequest' object has no attribute 'Session'
2017-03-09 15:04:51,504 [Thread-4:123145389277184] [django.request:284] [base:handle_uncaught_exception] [ERROR]- Internal Server Error: /index/add_staffs
Traceback (most recent call last):
  File "/Users/user/project_env/dssms_env/lib/python2.7/site-packages/django/core/handlers/base.py", line 149, in get_response
    response = self.process_exception_by_middleware(e, request)
  File "/Users/user/project_env/dssms_env/lib/python2.7/site-packages/django/core/handlers/base.py", line 147, in get_response
    response = wrapped_callback(request, *callback_args, **callback_kwargs)
  File "/Users/user/project_env/dssms_env/lib/python2.7/site-packages/django/views/generic/base.py", line 68, in view
    return self.dispatch(request, *args, **kwargs)
  File "/Users/user/project_env/dssms_env/lib/python2.7/site-packages/django/views/generic/base.py", line 88, in dispatch
    return handler(request, *args, **kwargs)
  File "/Users/user/workspace/Python/web/dssms_project/company/views.py", line 134, in get
    companyname = request.Session['companyname']
AttributeError: 'WSGIRequest' object has no attribute 'Session'
2017-03-09 15:04:52,767 [Thread-5:123145389277184] [django.request:284] [base:handle_uncaught_exception] [ERROR]- Internal Server Error: /index/add_staffs
Traceback (most recent call last):
  File "/Users/user/project_env/dssms_env/lib/python2.7/site-packages/django/core/handlers/base.py", line 149, in get_response
    response = self.process_exception_by_middleware(e, request)
  File "/Users/user/project_env/dssms_env/lib/python2.7/site-packages/django/core/handlers/base.py", line 147, in get_response
    response = wrapped_callback(request, *callback_args, **callback_kwargs)
  File "/Users/user/project_env/dssms_env/lib/python2.7/site-packages/django/views/generic/base.py", line 68, in view
    return self.dispatch(request, *args, **kwargs)
  File "/Users/user/project_env/dssms_env/lib/python2.7/site-packages/django/views/generic/base.py", line 88, in dispatch
    return handler(request, *args, **kwargs)
  File "/Users/user/workspace/Python/web/dssms_project/company/views.py", line 134, in get
    companyname = request.Session['companyname']
AttributeError: 'WSGIRequest' object has no attribute 'Session'
2017-03-09 15:05:00,241 [Thread-7:123145393483776] [django.request:284] [base:handle_uncaught_exception] [ERROR]- Internal Server Error: /login/
Traceback (most recent call last):
  File "/Users/user/project_env/dssms_env/lib/python2.7/site-packages/django/core/handlers/base.py", line 149, in get_response
    response = self.process_exception_by_middleware(e, request)
  File "/Users/user/project_env/dssms_env/lib/python2.7/site-packages/django/core/handlers/base.py", line 147, in get_response
    response = wrapped_callback(request, *callback_args, **callback_kwargs)
  File "/Users/user/project_env/dssms_env/lib/python2.7/site-packages/django/views/generic/base.py", line 68, in view
    return self.dispatch(request, *args, **kwargs)
  File "/Users/user/project_env/dssms_env/lib/python2.7/site-packages/django/views/generic/base.py", line 88, in dispatch
    return handler(request, *args, **kwargs)
  File "/Users/user/workspace/Python/web/dssms_project/company/views.py", line 32, in post
    request.Session['companyname'] = companyname
AttributeError: 'WSGIRequest' object has no attribute 'Session'
2017-03-09 15:23:56,657 [Thread-12:123145477963776] [django.request:103] [csrf:_reject] [WARNING]- Forbidden (CSRF token missing or incorrect.): /login/
2017-03-09 15:25:38,271 [Thread-23:123145477963776] [django.request:103] [csrf:_reject] [WARNING]- Forbidden (CSRF token missing or incorrect.): /index/add_departments
2017-03-09 16:28:20,201 [Thread-8:123145385897984] [django.request:103] [csrf:_reject] [WARNING]- Forbidden (CSRF token missing or incorrect.): /login/
2017-03-09 16:30:00,975 [Thread-20:123145385897984] [django.request:103] [csrf:_reject] [WARNING]- Forbidden (CSRF token missing or incorrect.): /login/
2017-03-09 22:13:08,279 [Thread-22:12768] [django.request:182] [base:get_response] [WARNING]- Not Found: /favicon.ico
2017-03-09 22:14:06,670 [Thread-29:4252] [django.request:284] [base:handle_uncaught_exception] [ERROR]- Internal Server Error: /regist
Traceback (most recent call last):
  File "D:\python_env\dssms_env_for_win\lib\site-packages\django\core\handlers\base.py", line 149, in get_response
    response = self.process_exception_by_middleware(e, request)
  File "D:\python_env\dssms_env_for_win\lib\site-packages\django\core\handlers\base.py", line 147, in get_response
    response = wrapped_callback(request, *callback_args, **callback_kwargs)
  File "D:\python_env\dssms_env_for_win\lib\site-packages\django\views\generic\base.py", line 68, in view
    return self.dispatch(request, *args, **kwargs)
  File "D:\python_env\dssms_env_for_win\lib\site-packages\django\views\generic\base.py", line 88, in dispatch
    return handler(request, *args, **kwargs)
  File "D:\python_env\dssms_project\company\views.py", line 71, in post
    organization.save()
  File "D:\python_env\dssms_env_for_win\lib\site-packages\django\db\models\base.py", line 708, in save
    force_update=force_update, update_fields=update_fields)
  File "D:\python_env\dssms_env_for_win\lib\site-packages\django\db\models\base.py", line 736, in save_base
    updated = self._save_table(raw, cls, force_insert, force_update, using, update_fields)
  File "D:\python_env\dssms_env_for_win\lib\site-packages\django\db\models\base.py", line 801, in _save_table
    forced_update)
  File "D:\python_env\dssms_env_for_win\lib\site-packages\django\db\models\base.py", line 851, in _do_update
    return filtered._update(values) > 0
  File "D:\python_env\dssms_env_for_win\lib\site-packages\django\db\models\query.py", line 645, in _update
    return query.get_compiler(self.db).execute_sql(CURSOR)
  File "D:\python_env\dssms_env_for_win\lib\site-packages\django\db\models\sql\compiler.py", line 1149, in execute_sql
    cursor = super(SQLUpdateCompiler, self).execute_sql(result_type)
  File "D:\python_env\dssms_env_for_win\lib\site-packages\django\db\models\sql\compiler.py", line 848, in execute_sql
    cursor.execute(sql, params)
  File "D:\python_env\dssms_env_for_win\lib\site-packages\django\db\backends\utils.py", line 79, in execute
    return super(CursorDebugWrapper, self).execute(sql, params)
  File "D:\python_env\dssms_env_for_win\lib\site-packages\django\db\backends\utils.py", line 64, in execute
    return self.cursor.execute(sql, params)
  File "D:\python_env\dssms_env_for_win\lib\site-packages\django\db\utils.py", line 95, in __exit__
    six.reraise(dj_exc_type, dj_exc_value, traceback)
  File "D:\python_env\dssms_env_for_win\lib\site-packages\django\db\backends\utils.py", line 64, in execute
    return self.cursor.execute(sql, params)
  File "D:\python_env\dssms_env_for_win\lib\site-packages\django\db\backends\sqlite3\base.py", line 323, in execute
    return Database.Cursor.execute(self, query, params)
IntegrityError: NOT NULL constraint failed: company_organization.date_regedit
2017-03-09 22:14:52,680 [Thread-80:3260] [django.request:103] [csrf:_reject] [WARNING]- Forbidden (CSRF token missing or incorrect.): /index/add_departments
2017-03-09 22:15:18,992 [Thread-81:9916] [django.request:103] [csrf:_reject] [WARNING]- Forbidden (CSRF token missing or incorrect.): /index/add_departments
2017-03-09 22:26:21,825 [Thread-95:4200] [django.request:182] [base:get_response] [WARNING]- Not Found: /login/<!--
2017-03-09 22:27:14,974 [Thread-102:12552] [django.request:182] [base:get_response] [WARNING]- Not Found: /login/<!--
2017-03-09 22:28:34,703 [Thread-6:7276] [django.request:182] [base:get_response] [WARNING]- Not Found: /login/<!--
2017-03-09 22:30:56,726 [Thread-6:10048] [django.request:182] [base:get_response] [WARNING]- Not Found: /login/<!--
2017-03-09 22:48:38,683 [Thread-10:9140] [django.request:284] [base:handle_uncaught_exception] [ERROR]- Internal Server Error: /index/add_departments
Traceback (most recent call last):
  File "D:\python_env\dssms_env_for_win\lib\site-packages\django\core\handlers\base.py", line 149, in get_response
    response = self.process_exception_by_middleware(e, request)
  File "D:\python_env\dssms_env_for_win\lib\site-packages\django\core\handlers\base.py", line 147, in get_response
    response = wrapped_callback(request, *callback_args, **callback_kwargs)
  File "D:\python_env\dssms_env_for_win\lib\site-packages\django\views\generic\base.py", line 68, in view
    return self.dispatch(request, *args, **kwargs)
  File "D:\python_env\dssms_env_for_win\lib\site-packages\django\views\generic\base.py", line 88, in dispatch
    return handler(request, *args, **kwargs)
  File "D:/python_env/dssms_project\company\views.py", line 146, in post
    department_name = request.POST['departmentname']
  File "D:\python_env\dssms_env_for_win\lib\site-packages\django\utils\datastructures.py", line 85, in __getitem__
    raise MultiValueDictKeyError(repr(key))
MultiValueDictKeyError: "'departmentname'"
2017-03-09 22:50:30,657 [Thread-9:488] [django.request:103] [csrf:_reject] [WARNING]- Forbidden (CSRF token missing or incorrect.): /index/add_departments
2017-03-09 22:51:02,516 [Thread-9:1252] [django.request:103] [csrf:_reject] [WARNING]- Forbidden (CSRF token missing or incorrect.): /index/add_departments
2017-03-09 23:04:41,835 [Thread-7:7580] [django.request:284] [base:handle_uncaught_exception] [ERROR]- Internal Server Error: /index/add_departments
Traceback (most recent call last):
  File "D:\python_env\dssms_env_for_win\lib\site-packages\django\core\handlers\base.py", line 149, in get_response
    response = self.process_exception_by_middleware(e, request)
  File "D:\python_env\dssms_env_for_win\lib\site-packages\django\core\handlers\base.py", line 147, in get_response
    response = wrapped_callback(request, *callback_args, **callback_kwargs)
  File "D:\python_env\dssms_env_for_win\lib\site-packages\django\views\generic\base.py", line 68, in view
    return self.dispatch(request, *args, **kwargs)
  File "D:\python_env\dssms_env_for_win\lib\site-packages\django\views\generic\base.py", line 88, in dispatch
    return handler(request, *args, **kwargs)
TypeError: get() takes exactly 3 arguments (2 given)
2017-03-09 23:04:43,117 [Thread-9:4600] [django.request:284] [base:handle_uncaught_exception] [ERROR]- Internal Server Error: /index/add_departments
Traceback (most recent call last):
  File "D:\python_env\dssms_env_for_win\lib\site-packages\django\core\handlers\base.py", line 149, in get_response
    response = self.process_exception_by_middleware(e, request)
  File "D:\python_env\dssms_env_for_win\lib\site-packages\django\core\handlers\base.py", line 147, in get_response
    response = wrapped_callback(request, *callback_args, **callback_kwargs)
  File "D:\python_env\dssms_env_for_win\lib\site-packages\django\views\generic\base.py", line 68, in view
    return self.dispatch(request, *args, **kwargs)
  File "D:\python_env\dssms_env_for_win\lib\site-packages\django\views\generic\base.py", line 88, in dispatch
    return handler(request, *args, **kwargs)
TypeError: get() takes exactly 3 arguments (2 given)
2017-03-09 23:04:51,048 [Thread-13:9136] [django.request:284] [base:handle_uncaught_exception] [ERROR]- Internal Server Error: /index/add_departments
Traceback (most recent call last):
  File "D:\python_env\dssms_env_for_win\lib\site-packages\django\core\handlers\base.py", line 149, in get_response
    response = self.process_exception_by_middleware(e, request)
  File "D:\python_env\dssms_env_for_win\lib\site-packages\django\core\handlers\base.py", line 147, in get_response
    response = wrapped_callback(request, *callback_args, **callback_kwargs)
  File "D:\python_env\dssms_env_for_win\lib\site-packages\django\views\generic\base.py", line 68, in view
    return self.dispatch(request, *args, **kwargs)
  File "D:\python_env\dssms_env_for_win\lib\site-packages\django\views\generic\base.py", line 88, in dispatch
    return handler(request, *args, **kwargs)
TypeError: get() takes exactly 3 arguments (2 given)
2017-03-09 23:04:53,269 [Thread-15:7476] [django.request:284] [base:handle_uncaught_exception] [ERROR]- Internal Server Error: /index/add_departments
Traceback (most recent call last):
  File "D:\python_env\dssms_env_for_win\lib\site-packages\django\core\handlers\base.py", line 149, in get_response
    response = self.process_exception_by_middleware(e, request)
  File "D:\python_env\dssms_env_for_win\lib\site-packages\django\core\handlers\base.py", line 147, in get_response
    response = wrapped_callback(request, *callback_args, **callback_kwargs)
  File "D:\python_env\dssms_env_for_win\lib\site-packages\django\views\generic\base.py", line 68, in view
    return self.dispatch(request, *args, **kwargs)
  File "D:\python_env\dssms_env_for_win\lib\site-packages\django\views\generic\base.py", line 88, in dispatch
    return handler(request, *args, **kwargs)
TypeError: get() takes exactly 3 arguments (2 given)
2017-03-09 23:11:00,894 [Thread-28:11536] [django.request:182] [base:get_response] [WARNING]- Not Found: /favicon.ico
2017-03-09 23:11:00,911 [Thread-29:8656] [django.request:182] [base:get_response] [WARNING]- Not Found: /favicon.ico
2017-03-09 23:13:00,479 [Thread-81:9744] [django.request:182] [base:get_response] [WARNING]- Not Found: /favicon.ico
2017-03-09 23:13:00,520 [Thread-82:2356] [django.request:182] [base:get_response] [WARNING]- Not Found: /favicon.ico
2017-03-09 23:22:30,223 [Thread-7:10768] [django.request:284] [base:handle_uncaught_exception] [ERROR]- Internal Server Error: /index/add_departments
Traceback (most recent call last):
  File "D:\python_env\dssms_env_for_win\lib\site-packages\django\core\handlers\base.py", line 149, in get_response
    response = self.process_exception_by_middleware(e, request)
  File "D:\python_env\dssms_env_for_win\lib\site-packages\django\core\handlers\base.py", line 147, in get_response
    response = wrapped_callback(request, *callback_args, **callback_kwargs)
  File "D:\python_env\dssms_env_for_win\lib\site-packages\django\views\generic\base.py", line 68, in view
    return self.dispatch(request, *args, **kwargs)
  File "D:\python_env\dssms_env_for_win\lib\site-packages\django\views\generic\base.py", line 88, in dispatch
    return handler(request, *args, **kwargs)
  File "D:/python_env/dssms_project\company\views.py", line 148, in post
    department = Department.objects.get(organization__company_name__contains=companyname, department_name__contains=department_name)
  File "D:\python_env\dssms_env_for_win\lib\site-packages\django\db\models\manager.py", line 122, in manager_method
    return getattr(self.get_queryset(), name)(*args, **kwargs)
  File "D:\python_env\dssms_env_for_win\lib\site-packages\django\db\models\query.py", line 387, in get
    self.model._meta.object_name
DoesNotExist: Department matching query does not exist.
2017-03-09 23:23:03,293 [Thread-13:12252] [django.request:284] [base:handle_uncaught_exception] [ERROR]- Internal Server Error: /index/add_departments
Traceback (most recent call last):
  File "D:\python_env\dssms_env_for_win\lib\site-packages\django\core\handlers\base.py", line 149, in get_response
    response = self.process_exception_by_middleware(e, request)
  File "D:\python_env\dssms_env_for_win\lib\site-packages\django\core\handlers\base.py", line 147, in get_response
    response = wrapped_callback(request, *callback_args, **callback_kwargs)
  File "D:\python_env\dssms_env_for_win\lib\site-packages\django\views\generic\base.py", line 68, in view
    return self.dispatch(request, *args, **kwargs)
  File "D:\python_env\dssms_env_for_win\lib\site-packages\django\views\generic\base.py", line 88, in dispatch
    return handler(request, *args, **kwargs)
  File "D:/python_env/dssms_project\company\views.py", line 148, in post
    department = Department.objects.get(organization__company_name__contains=companyname, department_name__contains=department_name)
  File "D:\python_env\dssms_env_for_win\lib\site-packages\django\db\models\manager.py", line 122, in manager_method
    return getattr(self.get_queryset(), name)(*args, **kwargs)
  File "D:\python_env\dssms_env_for_win\lib\site-packages\django\db\models\query.py", line 387, in get
    self.model._meta.object_name
DoesNotExist: Department matching query does not exist.
2017-03-09 23:24:47,898 [Thread-9:6300] [django.request:284] [base:handle_uncaught_exception] [ERROR]- Internal Server Error: /index/add_departments
Traceback (most recent call last):
  File "D:\python_env\dssms_env_for_win\lib\site-packages\django\core\handlers\base.py", line 149, in get_response
    response = self.process_exception_by_middleware(e, request)
  File "D:\python_env\dssms_env_for_win\lib\site-packages\django\core\handlers\base.py", line 147, in get_response
    response = wrapped_callback(request, *callback_args, **callback_kwargs)
  File "D:\python_env\dssms_env_for_win\lib\site-packages\django\views\generic\base.py", line 68, in view
    return self.dispatch(request, *args, **kwargs)
  File "D:\python_env\dssms_env_for_win\lib\site-packages\django\views\generic\base.py", line 88, in dispatch
    return handler(request, *args, **kwargs)
  File "D:/python_env/dssms_project\company\views.py", line 148, in post
    department = Department.objects.get(organization__company_name__contains=companyname, department_name=department_name)
  File "D:\python_env\dssms_env_for_win\lib\site-packages\django\db\models\manager.py", line 122, in manager_method
    return getattr(self.get_queryset(), name)(*args, **kwargs)
  File "D:\python_env\dssms_env_for_win\lib\site-packages\django\db\models\query.py", line 387, in get
    self.model._meta.object_name
DoesNotExist: Department matching query does not exist.
2017-03-09 23:28:26,605 [Thread-11:10048] [django.request:182] [base:get_response] [WARNING]- Not Found: /login/<!--
2017-03-09 23:28:37,483 [Thread-15:4688] [django.request:182] [base:get_response] [WARNING]- Not Found: /login/<!--
2017-03-09 23:30:00,447 [Thread-12:7856] [django.request:284] [base:handle_uncaught_exception] [ERROR]- Internal Server Error: /index/add_departments
Traceback (most recent call last):
  File "D:\python_env\dssms_env_for_win\lib\site-packages\django\core\handlers\base.py", line 149, in get_response
    response = self.process_exception_by_middleware(e, request)
  File "D:\python_env\dssms_env_for_win\lib\site-packages\django\core\handlers\base.py", line 147, in get_response
    response = wrapped_callback(request, *callback_args, **callback_kwargs)
  File "D:\python_env\dssms_env_for_win\lib\site-packages\django\views\generic\base.py", line 68, in view
    return self.dispatch(request, *args, **kwargs)
  File "D:\python_env\dssms_env_for_win\lib\site-packages\django\views\generic\base.py", line 88, in dispatch
    return handler(request, *args, **kwargs)
  File "D:/python_env/dssms_project\company\views.py", line 148, in post
    department = Department.objects.get(organization__company_name__contains=companyname, department_name=department_name)
  File "D:\python_env\dssms_env_for_win\lib\site-packages\django\db\models\manager.py", line 122, in manager_method
    return getattr(self.get_queryset(), name)(*args, **kwargs)
  File "D:\python_env\dssms_env_for_win\lib\site-packages\django\db\models\query.py", line 387, in get
    self.model._meta.object_name
DoesNotExist: Department matching query does not exist.
2017-03-09 23:30:44,973 [Thread-15:10564] [django.request:284] [base:handle_uncaught_exception] [ERROR]- Internal Server Error: /index/add_departments
Traceback (most recent call last):
  File "D:\python_env\dssms_env_for_win\lib\site-packages\django\core\handlers\base.py", line 149, in get_response
    response = self.process_exception_by_middleware(e, request)
  File "D:\python_env\dssms_env_for_win\lib\site-packages\django\core\handlers\base.py", line 147, in get_response
    response = wrapped_callback(request, *callback_args, **callback_kwargs)
  File "D:\python_env\dssms_env_for_win\lib\site-packages\django\views\generic\base.py", line 68, in view
    return self.dispatch(request, *args, **kwargs)
  File "D:\python_env\dssms_env_for_win\lib\site-packages\django\views\generic\base.py", line 88, in dispatch
    return handler(request, *args, **kwargs)
  File "D:/python_env/dssms_project\company\views.py", line 148, in post
    department = Department.objects.get(organization__company_name__contains=companyname, department_name=department_name)
  File "D:\python_env\dssms_env_for_win\lib\site-packages\django\db\models\manager.py", line 122, in manager_method
    return getattr(self.get_queryset(), name)(*args, **kwargs)
  File "D:\python_env\dssms_env_for_win\lib\site-packages\django\db\models\query.py", line 387, in get
    self.model._meta.object_name
DoesNotExist: Department matching query does not exist.
2017-03-09 23:38:31,013 [Thread-11:4728] [django.request:284] [base:handle_uncaught_exception] [ERROR]- Internal Server Error: /index/add_departments
Traceback (most recent call last):
  File "D:\python_env\dssms_env_for_win\lib\site-packages\django\core\handlers\base.py", line 149, in get_response
    response = self.process_exception_by_middleware(e, request)
  File "D:\python_env\dssms_env_for_win\lib\site-packages\django\core\handlers\base.py", line 147, in get_response
    response = wrapped_callback(request, *callback_args, **callback_kwargs)
  File "D:\python_env\dssms_env_for_win\lib\site-packages\django\views\generic\base.py", line 68, in view
    return self.dispatch(request, *args, **kwargs)
  File "D:\python_env\dssms_env_for_win\lib\site-packages\django\views\generic\base.py", line 88, in dispatch
    return handler(request, *args, **kwargs)
  File "D:/python_env/dssms_project\company\views.py", line 148, in post
    department = Department.objects.get(organization__company_name__contains=companyname, department_name=department_name)
  File "D:\python_env\dssms_env_for_win\lib\site-packages\django\db\models\manager.py", line 122, in manager_method
    return getattr(self.get_queryset(), name)(*args, **kwargs)
  File "D:\python_env\dssms_env_for_win\lib\site-packages\django\db\models\query.py", line 387, in get
    self.model._meta.object_name
DoesNotExist: Department matching query does not exist.
2017-03-09 23:39:17,217 [Thread-7:8288] [django.request:284] [base:handle_uncaught_exception] [ERROR]- Internal Server Error: /index/add_departments
Traceback (most recent call last):
  File "D:\python_env\dssms_env_for_win\lib\site-packages\django\core\handlers\base.py", line 149, in get_response
    response = self.process_exception_by_middleware(e, request)
  File "D:\python_env\dssms_env_for_win\lib\site-packages\django\core\handlers\base.py", line 147, in get_response
    response = wrapped_callback(request, *callback_args, **callback_kwargs)
  File "D:\python_env\dssms_env_for_win\lib\site-packages\django\views\generic\base.py", line 68, in view
    return self.dispatch(request, *args, **kwargs)
  File "D:\python_env\dssms_env_for_win\lib\site-packages\django\views\generic\base.py", line 88, in dispatch
    return handler(request, *args, **kwargs)
  File "D:/python_env/dssms_project\company\views.py", line 148, in post
    department = Department.objects.get(organization__company_name__contains=companyname, department_name__contains=department_name)
  File "D:\python_env\dssms_env_for_win\lib\site-packages\django\db\models\manager.py", line 122, in manager_method
    return getattr(self.get_queryset(), name)(*args, **kwargs)
  File "D:\python_env\dssms_env_for_win\lib\site-packages\django\db\models\query.py", line 387, in get
    self.model._meta.object_name
DoesNotExist: Department matching query does not exist.
2017-03-09 23:39:32,638 [Thread-8:5192] [django.request:284] [base:handle_uncaught_exception] [ERROR]- Internal Server Error: /index/add_departments
Traceback (most recent call last):
  File "D:\python_env\dssms_env_for_win\lib\site-packages\django\core\handlers\base.py", line 149, in get_response
    response = self.process_exception_by_middleware(e, request)
  File "D:\python_env\dssms_env_for_win\lib\site-packages\django\core\handlers\base.py", line 147, in get_response
    response = wrapped_callback(request, *callback_args, **callback_kwargs)
  File "D:\python_env\dssms_env_for_win\lib\site-packages\django\views\generic\base.py", line 68, in view
    return self.dispatch(request, *args, **kwargs)
  File "D:\python_env\dssms_env_for_win\lib\site-packages\django\views\generic\base.py", line 88, in dispatch
    return handler(request, *args, **kwargs)
  File "D:/python_env/dssms_project\company\views.py", line 148, in post
    department = Department.objects.get(organization__company_name__contains=companyname, department_name__contains=department_name)
  File "D:\python_env\dssms_env_for_win\lib\site-packages\django\db\models\manager.py", line 122, in manager_method
    return getattr(self.get_queryset(), name)(*args, **kwargs)
  File "D:\python_env\dssms_env_for_win\lib\site-packages\django\db\models\query.py", line 387, in get
    self.model._meta.object_name
DoesNotExist: Department matching query does not exist.
2017-03-09 23:40:15,907 [Thread-7:5316] [django.request:284] [base:handle_uncaught_exception] [ERROR]- Internal Server Error: /index/add_departments
Traceback (most recent call last):
  File "D:\python_env\dssms_env_for_win\lib\site-packages\django\core\handlers\base.py", line 149, in get_response
    response = self.process_exception_by_middleware(e, request)
  File "D:\python_env\dssms_env_for_win\lib\site-packages\django\core\handlers\base.py", line 147, in get_response
    response = wrapped_callback(request, *callback_args, **callback_kwargs)
  File "D:\python_env\dssms_env_for_win\lib\site-packages\django\views\generic\base.py", line 68, in view
    return self.dispatch(request, *args, **kwargs)
  File "D:\python_env\dssms_env_for_win\lib\site-packages\django\views\generic\base.py", line 88, in dispatch
    return handler(request, *args, **kwargs)
  File "D:/python_env/dssms_project\company\views.py", line 148, in post
    department = Department.objects.get(organization__company_name=companyname, department_name=department_name)
  File "D:\python_env\dssms_env_for_win\lib\site-packages\django\db\models\manager.py", line 122, in manager_method
    return getattr(self.get_queryset(), name)(*args, **kwargs)
  File "D:\python_env\dssms_env_for_win\lib\site-packages\django\db\models\query.py", line 387, in get
    self.model._meta.object_name
DoesNotExist: Department matching query does not exist.
2017-03-09 23:43:36,298 [Thread-9:4284] [django.request:284] [base:handle_uncaught_exception] [ERROR]- Internal Server Error: /index/add_departments
Traceback (most recent call last):
  File "D:\python_env\dssms_env_for_win\lib\site-packages\django\core\handlers\base.py", line 149, in get_response
    response = self.process_exception_by_middleware(e, request)
  File "D:\python_env\dssms_env_for_win\lib\site-packages\django\core\handlers\base.py", line 147, in get_response
    response = wrapped_callback(request, *callback_args, **callback_kwargs)
  File "D:\python_env\dssms_env_for_win\lib\site-packages\django\views\generic\base.py", line 68, in view
    return self.dispatch(request, *args, **kwargs)
  File "D:\python_env\dssms_env_for_win\lib\site-packages\django\views\generic\base.py", line 88, in dispatch
    return handler(request, *args, **kwargs)
  File "D:/python_env/dssms_project\company\views.py", line 148, in post
    department = Department.objects.get(organization__company_name=companyname, department_name=department_name)
  File "D:\python_env\dssms_env_for_win\lib\site-packages\django\db\models\manager.py", line 122, in manager_method
    return getattr(self.get_queryset(), name)(*args, **kwargs)
  File "D:\python_env\dssms_env_for_win\lib\site-packages\django\db\models\query.py", line 387, in get
    self.model._meta.object_name
DoesNotExist: Department matching query does not exist.
2017-03-09 23:56:49,036 [Thread-15:1168] [django.request:284] [base:handle_uncaught_exception] [ERROR]- Internal Server Error: /index/add_departments
Traceback (most recent call last):
  File "D:\python_env\dssms_env_for_win\lib\site-packages\django\core\handlers\base.py", line 149, in get_response
    response = self.process_exception_by_middleware(e, request)
  File "D:\python_env\dssms_env_for_win\lib\site-packages\django\core\handlers\base.py", line 147, in get_response
    response = wrapped_callback(request, *callback_args, **callback_kwargs)
  File "D:\python_env\dssms_env_for_win\lib\site-packages\django\views\generic\base.py", line 68, in view
    return self.dispatch(request, *args, **kwargs)
  File "D:\python_env\dssms_env_for_win\lib\site-packages\django\views\generic\base.py", line 88, in dispatch
    return handler(request, *args, **kwargs)
  File "D:/python_env/dssms_project\company\views.py", line 149, in post
    department = Department.objects.get(organization__company_name=companyname, department_name=department_name)
  File "D:\python_env\dssms_env_for_win\lib\site-packages\django\db\models\manager.py", line 122, in manager_method
    return getattr(self.get_queryset(), name)(*args, **kwargs)
  File "D:\python_env\dssms_env_for_win\lib\site-packages\django\db\models\query.py", line 387, in get
    self.model._meta.object_name
DoesNotExist: Department matching query does not exist.
2017-03-10 00:01:31,640 [Thread-13:7900] [django.request:284] [base:handle_uncaught_exception] [ERROR]- Internal Server Error: /regist
Traceback (most recent call last):
  File "D:\python_env\dssms_env_for_win\lib\site-packages\django\core\handlers\base.py", line 149, in get_response
    response = self.process_exception_by_middleware(e, request)
  File "D:\python_env\dssms_env_for_win\lib\site-packages\django\core\handlers\base.py", line 147, in get_response
    response = wrapped_callback(request, *callback_args, **callback_kwargs)
  File "D:\python_env\dssms_env_for_win\lib\site-packages\django\views\generic\base.py", line 68, in view
    return self.dispatch(request, *args, **kwargs)
  File "D:\python_env\dssms_env_for_win\lib\site-packages\django\views\generic\base.py", line 88, in dispatch
    return handler(request, *args, **kwargs)
  File "D:/python_env/dssms_project\company\views.py", line 79, in post
    duty.save()
  File "D:\python_env\dssms_env_for_win\lib\site-packages\django\db\models\base.py", line 708, in save
    force_update=force_update, update_fields=update_fields)
  File "D:\python_env\dssms_env_for_win\lib\site-packages\django\db\models\base.py", line 736, in save_base
    updated = self._save_table(raw, cls, force_insert, force_update, using, update_fields)
  File "D:\python_env\dssms_env_for_win\lib\site-packages\django\db\models\base.py", line 820, in _save_table
    result = self._do_insert(cls._base_manager, using, fields, update_pk, raw)
  File "D:\python_env\dssms_env_for_win\lib\site-packages\django\db\models\base.py", line 859, in _do_insert
    using=using, raw=raw)
  File "D:\python_env\dssms_env_for_win\lib\site-packages\django\db\models\manager.py", line 122, in manager_method
    return getattr(self.get_queryset(), name)(*args, **kwargs)
  File "D:\python_env\dssms_env_for_win\lib\site-packages\django\db\models\query.py", line 1039, in _insert
    return query.get_compiler(using=using).execute_sql(return_id)
  File "D:\python_env\dssms_env_for_win\lib\site-packages\django\db\models\sql\compiler.py", line 1060, in execute_sql
    cursor.execute(sql, params)
  File "D:\python_env\dssms_env_for_win\lib\site-packages\django\db\backends\utils.py", line 79, in execute
    return super(CursorDebugWrapper, self).execute(sql, params)
  File "D:\python_env\dssms_env_for_win\lib\site-packages\django\db\backends\utils.py", line 64, in execute
    return self.cursor.execute(sql, params)
  File "D:\python_env\dssms_env_for_win\lib\site-packages\django\db\utils.py", line 95, in __exit__
    six.reraise(dj_exc_type, dj_exc_value, traceback)
  File "D:\python_env\dssms_env_for_win\lib\site-packages\django\db\backends\utils.py", line 64, in execute
    return self.cursor.execute(sql, params)
  File "D:\python_env\dssms_env_for_win\lib\site-packages\django\db\backends\sqlite3\base.py", line 323, in execute
    return Database.Cursor.execute(self, query, params)
IntegrityError: NOT NULL constraint failed: company_duty.department_id
2017-03-10 00:03:01,803 [Thread-13:12816] [django.request:284] [base:handle_uncaught_exception] [ERROR]- Internal Server Error: /regist
Traceback (most recent call last):
  File "D:\python_env\dssms_env_for_win\lib\site-packages\django\core\handlers\base.py", line 149, in get_response
    response = self.process_exception_by_middleware(e, request)
  File "D:\python_env\dssms_env_for_win\lib\site-packages\django\core\handlers\base.py", line 147, in get_response
    response = wrapped_callback(request, *callback_args, **callback_kwargs)
  File "D:\python_env\dssms_env_for_win\lib\site-packages\django\views\generic\base.py", line 68, in view
    return self.dispatch(request, *args, **kwargs)
  File "D:\python_env\dssms_env_for_win\lib\site-packages\django\views\generic\base.py", line 88, in dispatch
    return handler(request, *args, **kwargs)
  File "D:/python_env/dssms_project\company\views.py", line 70, in post
    organization.save()
  File "D:\python_env\dssms_env_for_win\lib\site-packages\django\db\models\base.py", line 708, in save
    force_update=force_update, update_fields=update_fields)
  File "D:\python_env\dssms_env_for_win\lib\site-packages\django\db\models\base.py", line 736, in save_base
    updated = self._save_table(raw, cls, force_insert, force_update, using, update_fields)
  File "D:\python_env\dssms_env_for_win\lib\site-packages\django\db\models\base.py", line 801, in _save_table
    forced_update)
  File "D:\python_env\dssms_env_for_win\lib\site-packages\django\db\models\base.py", line 851, in _do_update
    return filtered._update(values) > 0
  File "D:\python_env\dssms_env_for_win\lib\site-packages\django\db\models\query.py", line 645, in _update
    return query.get_compiler(self.db).execute_sql(CURSOR)
  File "D:\python_env\dssms_env_for_win\lib\site-packages\django\db\models\sql\compiler.py", line 1149, in execute_sql
    cursor = super(SQLUpdateCompiler, self).execute_sql(result_type)
  File "D:\python_env\dssms_env_for_win\lib\site-packages\django\db\models\sql\compiler.py", line 848, in execute_sql
    cursor.execute(sql, params)
  File "D:\python_env\dssms_env_for_win\lib\site-packages\django\db\backends\utils.py", line 79, in execute
    return super(CursorDebugWrapper, self).execute(sql, params)
  File "D:\python_env\dssms_env_for_win\lib\site-packages\django\db\backends\utils.py", line 64, in execute
    return self.cursor.execute(sql, params)
  File "D:\python_env\dssms_env_for_win\lib\site-packages\django\db\utils.py", line 95, in __exit__
    six.reraise(dj_exc_type, dj_exc_value, traceback)
  File "D:\python_env\dssms_env_for_win\lib\site-packages\django\db\backends\utils.py", line 64, in execute
    return self.cursor.execute(sql, params)
  File "D:\python_env\dssms_env_for_win\lib\site-packages\django\db\backends\sqlite3\base.py", line 323, in execute
    return Database.Cursor.execute(self, query, params)
IntegrityError: NOT NULL constraint failed: company_organization.date_regedit
2017-03-10 00:04:51,434 [Thread-13:7900] [django.request:284] [base:handle_uncaught_exception] [ERROR]- Internal Server Error: /regist
Traceback (most recent call last):
  File "D:\python_env\dssms_env_for_win\lib\site-packages\django\core\handlers\base.py", line 149, in get_response
    response = self.process_exception_by_middleware(e, request)
  File "D:\python_env\dssms_env_for_win\lib\site-packages\django\core\handlers\base.py", line 147, in get_response
    response = wrapped_callback(request, *callback_args, **callback_kwargs)
  File "D:\python_env\dssms_env_for_win\lib\site-packages\django\views\generic\base.py", line 68, in view
    return self.dispatch(request, *args, **kwargs)
  File "D:\python_env\dssms_env_for_win\lib\site-packages\django\views\generic\base.py", line 88, in dispatch
    return handler(request, *args, **kwargs)
  File "D:/python_env/dssms_project\company\views.py", line 107, in post
    staff.save()
  File "D:\python_env\dssms_env_for_win\lib\site-packages\django\contrib\auth\base_user.py", line 74, in save
    super(AbstractBaseUser, self).save(*args, **kwargs)
  File "D:\python_env\dssms_env_for_win\lib\site-packages\django\db\models\base.py", line 708, in save
    force_update=force_update, update_fields=update_fields)
  File "D:\python_env\dssms_env_for_win\lib\site-packages\django\db\models\base.py", line 736, in save_base
    updated = self._save_table(raw, cls, force_insert, force_update, using, update_fields)
  File "D:\python_env\dssms_env_for_win\lib\site-packages\django\db\models\base.py", line 820, in _save_table
    result = self._do_insert(cls._base_manager, using, fields, update_pk, raw)
  File "D:\python_env\dssms_env_for_win\lib\site-packages\django\db\models\base.py", line 859, in _do_insert
    using=using, raw=raw)
  File "D:\python_env\dssms_env_for_win\lib\site-packages\django\db\models\manager.py", line 122, in manager_method
    return getattr(self.get_queryset(), name)(*args, **kwargs)
  File "D:\python_env\dssms_env_for_win\lib\site-packages\django\db\models\query.py", line 1039, in _insert
    return query.get_compiler(using=using).execute_sql(return_id)
  File "D:\python_env\dssms_env_for_win\lib\site-packages\django\db\models\sql\compiler.py", line 1060, in execute_sql
    cursor.execute(sql, params)
  File "D:\python_env\dssms_env_for_win\lib\site-packages\django\db\backends\utils.py", line 79, in execute
    return super(CursorDebugWrapper, self).execute(sql, params)
  File "D:\python_env\dssms_env_for_win\lib\site-packages\django\db\backends\utils.py", line 64, in execute
    return self.cursor.execute(sql, params)
  File "D:\python_env\dssms_env_for_win\lib\site-packages\django\db\utils.py", line 95, in __exit__
    six.reraise(dj_exc_type, dj_exc_value, traceback)
  File "D:\python_env\dssms_env_for_win\lib\site-packages\django\db\backends\utils.py", line 64, in execute
    return self.cursor.execute(sql, params)
  File "D:\python_env\dssms_env_for_win\lib\site-packages\django\db\backends\sqlite3\base.py", line 323, in execute
    return Database.Cursor.execute(self, query, params)
IntegrityError: NOT NULL constraint failed: company_staff.duty_id
2017-03-10 00:05:53,112 [Thread-20:13264] [django.request:284] [base:handle_uncaught_exception] [ERROR]- Internal Server Error: /regist
Traceback (most recent call last):
  File "D:\python_env\dssms_env_for_win\lib\site-packages\django\core\handlers\base.py", line 149, in get_response
    response = self.process_exception_by_middleware(e, request)
  File "D:\python_env\dssms_env_for_win\lib\site-packages\django\core\handlers\base.py", line 147, in get_response
    response = wrapped_callback(request, *callback_args, **callback_kwargs)
  File "D:\python_env\dssms_env_for_win\lib\site-packages\django\views\generic\base.py", line 68, in view
    return self.dispatch(request, *args, **kwargs)
  File "D:\python_env\dssms_env_for_win\lib\site-packages\django\views\generic\base.py", line 88, in dispatch
    return handler(request, *args, **kwargs)
  File "D:/python_env/dssms_project\company\views.py", line 107, in post
    staff.password = make_password(password)
  File "D:\python_env\dssms_env_for_win\lib\site-packages\django\contrib\auth\base_user.py", line 74, in save
    super(AbstractBaseUser, self).save(*args, **kwargs)
  File "D:\python_env\dssms_env_for_win\lib\site-packages\django\db\models\base.py", line 708, in save
    force_update=force_update, update_fields=update_fields)
  File "D:\python_env\dssms_env_for_win\lib\site-packages\django\db\models\base.py", line 736, in save_base
    updated = self._save_table(raw, cls, force_insert, force_update, using, update_fields)
  File "D:\python_env\dssms_env_for_win\lib\site-packages\django\db\models\base.py", line 820, in _save_table
    result = self._do_insert(cls._base_manager, using, fields, update_pk, raw)
  File "D:\python_env\dssms_env_for_win\lib\site-packages\django\db\models\base.py", line 859, in _do_insert
    using=using, raw=raw)
  File "D:\python_env\dssms_env_for_win\lib\site-packages\django\db\models\manager.py", line 122, in manager_method
    return getattr(self.get_queryset(), name)(*args, **kwargs)
  File "D:\python_env\dssms_env_for_win\lib\site-packages\django\db\models\query.py", line 1039, in _insert
    return query.get_compiler(using=using).execute_sql(return_id)
  File "D:\python_env\dssms_env_for_win\lib\site-packages\django\db\models\sql\compiler.py", line 1060, in execute_sql
    cursor.execute(sql, params)
  File "D:\python_env\dssms_env_for_win\lib\site-packages\django\db\backends\utils.py", line 79, in execute
    return super(CursorDebugWrapper, self).execute(sql, params)
  File "D:\python_env\dssms_env_for_win\lib\site-packages\django\db\backends\utils.py", line 64, in execute
    return self.cursor.execute(sql, params)
  File "D:\python_env\dssms_env_for_win\lib\site-packages\django\db\utils.py", line 95, in __exit__
    six.reraise(dj_exc_type, dj_exc_value, traceback)
  File "D:\python_env\dssms_env_for_win\lib\site-packages\django\db\backends\utils.py", line 64, in execute
    return self.cursor.execute(sql, params)
  File "D:\python_env\dssms_env_for_win\lib\site-packages\django\db\backends\sqlite3\base.py", line 323, in execute
    return Database.Cursor.execute(self, query, params)
IntegrityError: NOT NULL constraint failed: company_staff.duty_id
2017-03-10 00:07:12,413 [Thread-21:11912] [django.request:284] [base:handle_uncaught_exception] [ERROR]- Internal Server Error: /index/add_departments
Traceback (most recent call last):
  File "D:\python_env\dssms_env_for_win\lib\site-packages\django\core\handlers\base.py", line 149, in get_response
    response = self.process_exception_by_middleware(e, request)
  File "D:\python_env\dssms_env_for_win\lib\site-packages\django\core\handlers\base.py", line 147, in get_response
    response = wrapped_callback(request, *callback_args, **callback_kwargs)
  File "D:\python_env\dssms_env_for_win\lib\site-packages\django\views\generic\base.py", line 68, in view
    return self.dispatch(request, *args, **kwargs)
  File "D:\python_env\dssms_env_for_win\lib\site-packages\django\views\generic\base.py", line 88, in dispatch
    return handler(request, *args, **kwargs)
  File "D:/python_env/dssms_project\company\views.py", line 150, in post
    department = Department.objects.get(organization__company_name=companyname, department_name=department_name)
  File "D:\python_env\dssms_env_for_win\lib\site-packages\django\db\models\manager.py", line 122, in manager_method
    return getattr(self.get_queryset(), name)(*args, **kwargs)
  File "D:\python_env\dssms_env_for_win\lib\site-packages\django\db\models\query.py", line 387, in get
    self.model._meta.object_name
DoesNotExist: Department matching query does not exist.
2017-03-10 00:08:10,144 [Thread-22:7856] [django.request:284] [base:handle_uncaught_exception] [ERROR]- Internal Server Error: /index/add_departments
Traceback (most recent call last):
  File "D:\python_env\dssms_env_for_win\lib\site-packages\django\core\handlers\base.py", line 149, in get_response
    response = self.process_exception_by_middleware(e, request)
  File "D:\python_env\dssms_env_for_win\lib\site-packages\django\core\handlers\base.py", line 147, in get_response
    response = wrapped_callback(request, *callback_args, **callback_kwargs)
  File "D:\python_env\dssms_env_for_win\lib\site-packages\django\views\generic\base.py", line 68, in view
    return self.dispatch(request, *args, **kwargs)
  File "D:\python_env\dssms_env_for_win\lib\site-packages\django\views\generic\base.py", line 88, in dispatch
    return handler(request, *args, **kwargs)
  File "D:/python_env/dssms_project\company\views.py", line 150, in post
    department = Department.objects.get(organization__company_name__contains=companyname, department_name=department_name)
  File "D:\python_env\dssms_env_for_win\lib\site-packages\django\db\models\manager.py", line 122, in manager_method
    return getattr(self.get_queryset(), name)(*args, **kwargs)
  File "D:\python_env\dssms_env_for_win\lib\site-packages\django\db\models\query.py", line 387, in get
    self.model._meta.object_name
DoesNotExist: Department matching query does not exist.
2017-03-10 00:15:52,200 [Thread-13:12964] [django.request:284] [base:handle_uncaught_exception] [ERROR]- Internal Server Error: /index/add_departments
Traceback (most recent call last):
  File "D:\python_env\dssms_env_for_win\lib\site-packages\django\core\handlers\base.py", line 149, in get_response
    response = self.process_exception_by_middleware(e, request)
  File "D:\python_env\dssms_env_for_win\lib\site-packages\django\core\handlers\base.py", line 147, in get_response
    response = wrapped_callback(request, *callback_args, **callback_kwargs)
  File "D:\python_env\dssms_env_for_win\lib\site-packages\django\views\generic\base.py", line 68, in view
    return self.dispatch(request, *args, **kwargs)
  File "D:\python_env\dssms_env_for_win\lib\site-packages\django\views\generic\base.py", line 88, in dispatch
    return handler(request, *args, **kwargs)
  File "D:/python_env/dssms_project\company\views.py", line 155, in post
    if department is None:
UnboundLocalError: local variable 'department' referenced before assignment
2017-03-10 00:17:38,158 [Thread-9:11336] [django.request:182] [base:get_response] [WARNING]- Not Found: /login/<!--
2017-03-10 00:17:41,645 [Thread-10:11800] [django.request:284] [base:handle_uncaught_exception] [ERROR]- Internal Server Error: /index/add_staffs
Traceback (most recent call last):
  File "D:\python_env\dssms_env_for_win\lib\site-packages\django\core\handlers\base.py", line 149, in get_response
    response = self.process_exception_by_middleware(e, request)
  File "D:\python_env\dssms_env_for_win\lib\site-packages\django\core\handlers\base.py", line 147, in get_response
    response = wrapped_callback(request, *callback_args, **callback_kwargs)
  File "D:\python_env\dssms_env_for_win\lib\site-packages\django\views\generic\base.py", line 68, in view
    return self.dispatch(request, *args, **kwargs)
  File "D:\python_env\dssms_env_for_win\lib\site-packages\django\views\generic\base.py", line 88, in dispatch
    return handler(request, *args, **kwargs)
  File "D:/python_env/dssms_project\company\views.py", line 134, in get
    companyname = request.session['companyname']
  File "D:\python_env\dssms_env_for_win\lib\site-packages\django\contrib\sessions\backends\base.py", line 50, in __getitem__
    return self._session[key]
KeyError: 'companyname'
2017-03-10 00:17:43,153 [Thread-11:9120] [django.request:284] [base:handle_uncaught_exception] [ERROR]- Internal Server Error: /index/add_staffs
Traceback (most recent call last):
  File "D:\python_env\dssms_env_for_win\lib\site-packages\django\core\handlers\base.py", line 149, in get_response
    response = self.process_exception_by_middleware(e, request)
  File "D:\python_env\dssms_env_for_win\lib\site-packages\django\core\handlers\base.py", line 147, in get_response
    response = wrapped_callback(request, *callback_args, **callback_kwargs)
  File "D:\python_env\dssms_env_for_win\lib\site-packages\django\views\generic\base.py", line 68, in view
    return self.dispatch(request, *args, **kwargs)
  File "D:\python_env\dssms_env_for_win\lib\site-packages\django\views\generic\base.py", line 88, in dispatch
    return handler(request, *args, **kwargs)
  File "D:/python_env/dssms_project\company\views.py", line 134, in get
    companyname = request.session['companyname']
  File "D:\python_env\dssms_env_for_win\lib\site-packages\django\contrib\sessions\backends\base.py", line 50, in __getitem__
    return self._session[key]
KeyError: 'companyname'
2017-03-10 00:17:43,315 [Thread-12:4200] [django.request:284] [base:handle_uncaught_exception] [ERROR]- Internal Server Error: /index/add_staffs
Traceback (most recent call last):
  File "D:\python_env\dssms_env_for_win\lib\site-packages\django\core\handlers\base.py", line 149, in get_response
    response = self.process_exception_by_middleware(e, request)
  File "D:\python_env\dssms_env_for_win\lib\site-packages\django\core\handlers\base.py", line 147, in get_response
    response = wrapped_callback(request, *callback_args, **callback_kwargs)
  File "D:\python_env\dssms_env_for_win\lib\site-packages\django\views\generic\base.py", line 68, in view
    return self.dispatch(request, *args, **kwargs)
  File "D:\python_env\dssms_env_for_win\lib\site-packages\django\views\generic\base.py", line 88, in dispatch
    return handler(request, *args, **kwargs)
  File "D:/python_env/dssms_project\company\views.py", line 134, in get
    companyname = request.session['companyname']
  File "D:\python_env\dssms_env_for_win\lib\site-packages\django\contrib\sessions\backends\base.py", line 50, in __getitem__
    return self._session[key]
KeyError: 'companyname'
2017-03-10 00:18:13,109 [Thread-16:11856] [django.request:182] [base:get_response] [WARNING]- Not Found: /login/<!--
2017-03-10 00:18:16,634 [Thread-17:10536] [django.request:284] [base:handle_uncaught_exception] [ERROR]- Internal Server Error: /index/add_staffs
Traceback (most recent call last):
  File "D:\python_env\dssms_env_for_win\lib\site-packages\django\core\handlers\base.py", line 149, in get_response
    response = self.process_exception_by_middleware(e, request)
  File "D:\python_env\dssms_env_for_win\lib\site-packages\django\core\handlers\base.py", line 147, in get_response
    response = wrapped_callback(request, *callback_args, **callback_kwargs)
  File "D:\python_env\dssms_env_for_win\lib\site-packages\django\views\generic\base.py", line 68, in view
    return self.dispatch(request, *args, **kwargs)
  File "D:\python_env\dssms_env_for_win\lib\site-packages\django\views\generic\base.py", line 88, in dispatch
    return handler(request, *args, **kwargs)
  File "D:/python_env/dssms_project\company\views.py", line 134, in get
    companyname = request.session['companyname']
  File "D:\python_env\dssms_env_for_win\lib\site-packages\django\contrib\sessions\backends\base.py", line 50, in __getitem__
    return self._session[key]
KeyError: 'companyname'
2017-03-10 00:18:17,107 [Thread-18:1144] [django.request:284] [base:handle_uncaught_exception] [ERROR]- Internal Server Error: /index/add_staffs
Traceback (most recent call last):
  File "D:\python_env\dssms_env_for_win\lib\site-packages\django\core\handlers\base.py", line 149, in get_response
    response = self.process_exception_by_middleware(e, request)
  File "D:\python_env\dssms_env_for_win\lib\site-packages\django\core\handlers\base.py", line 147, in get_response
    response = wrapped_callback(request, *callback_args, **callback_kwargs)
  File "D:\python_env\dssms_env_for_win\lib\site-packages\django\views\generic\base.py", line 68, in view
    return self.dispatch(request, *args, **kwargs)
  File "D:\python_env\dssms_env_for_win\lib\site-packages\django\views\generic\base.py", line 88, in dispatch
    return handler(request, *args, **kwargs)
  File "D:/python_env/dssms_project\company\views.py", line 134, in get
    companyname = request.session['companyname']
  File "D:\python_env\dssms_env_for_win\lib\site-packages\django\contrib\sessions\backends\base.py", line 50, in __getitem__
    return self._session[key]
KeyError: 'companyname'
2017-03-10 00:18:25,177 [Thread-23:740] [django.request:284] [base:handle_uncaught_exception] [ERROR]- Internal Server Error: /index/add_staffs
Traceback (most recent call last):
  File "D:\python_env\dssms_env_for_win\lib\site-packages\django\core\handlers\base.py", line 149, in get_response
    response = self.process_exception_by_middleware(e, request)
  File "D:\python_env\dssms_env_for_win\lib\site-packages\django\core\handlers\base.py", line 147, in get_response
    response = wrapped_callback(request, *callback_args, **callback_kwargs)
  File "D:\python_env\dssms_env_for_win\lib\site-packages\django\views\generic\base.py", line 68, in view
    return self.dispatch(request, *args, **kwargs)
  File "D:\python_env\dssms_env_for_win\lib\site-packages\django\views\generic\base.py", line 88, in dispatch
    return handler(request, *args, **kwargs)
  File "D:/python_env/dssms_project\company\views.py", line 134, in get
    companyname = request.session['companyname']
  File "D:\python_env\dssms_env_for_win\lib\site-packages\django\contrib\sessions\backends\base.py", line 50, in __getitem__
    return self._session[key]
KeyError: 'companyname'
2017-03-10 00:18:27,582 [Thread-26:2800] [django.request:182] [base:get_response] [WARNING]- Not Found: /login//
2017-03-10 00:18:32,895 [Thread-28:8328] [django.request:284] [base:handle_uncaught_exception] [ERROR]- Internal Server Error: /index/add_staffs
Traceback (most recent call last):
  File "D:\python_env\dssms_env_for_win\lib\site-packages\django\core\handlers\base.py", line 149, in get_response
    response = self.process_exception_by_middleware(e, request)
  File "D:\python_env\dssms_env_for_win\lib\site-packages\django\core\handlers\base.py", line 147, in get_response
    response = wrapped_callback(request, *callback_args, **callback_kwargs)
  File "D:\python_env\dssms_env_for_win\lib\site-packages\django\views\generic\base.py", line 68, in view
    return self.dispatch(request, *args, **kwargs)
  File "D:\python_env\dssms_env_for_win\lib\site-packages\django\views\generic\base.py", line 88, in dispatch
    return handler(request, *args, **kwargs)
  File "D:/python_env/dssms_project\company\views.py", line 134, in get
    companyname = request.session['companyname']
  File "D:\python_env\dssms_env_for_win\lib\site-packages\django\contrib\sessions\backends\base.py", line 50, in __getitem__
    return self._session[key]
KeyError: 'companyname'
2017-03-10 00:18:35,595 [Thread-30:9160] [django.request:284] [base:handle_uncaught_exception] [ERROR]- Internal Server Error: /index/add_staffs
Traceback (most recent call last):
  File "D:\python_env\dssms_env_for_win\lib\site-packages\django\core\handlers\base.py", line 149, in get_response
    response = self.process_exception_by_middleware(e, request)
  File "D:\python_env\dssms_env_for_win\lib\site-packages\django\core\handlers\base.py", line 147, in get_response
    response = wrapped_callback(request, *callback_args, **callback_kwargs)
  File "D:\python_env\dssms_env_for_win\lib\site-packages\django\views\generic\base.py", line 68, in view
    return self.dispatch(request, *args, **kwargs)
  File "D:\python_env\dssms_env_for_win\lib\site-packages\django\views\generic\base.py", line 88, in dispatch
    return handler(request, *args, **kwargs)
  File "D:/python_env/dssms_project\company\views.py", line 134, in get
    companyname = request.session['companyname']
  File "D:\python_env\dssms_env_for_win\lib\site-packages\django\contrib\sessions\backends\base.py", line 50, in __getitem__
    return self._session[key]
KeyError: 'companyname'
2017-03-10 00:18:36,460 [Thread-32:7492] [django.request:284] [base:handle_uncaught_exception] [ERROR]- Internal Server Error: /index/add_staffs
Traceback (most recent call last):
  File "D:\python_env\dssms_env_for_win\lib\site-packages\django\core\handlers\base.py", line 149, in get_response
    response = self.process_exception_by_middleware(e, request)
  File "D:\python_env\dssms_env_for_win\lib\site-packages\django\core\handlers\base.py", line 147, in get_response
    response = wrapped_callback(request, *callback_args, **callback_kwargs)
  File "D:\python_env\dssms_env_for_win\lib\site-packages\django\views\generic\base.py", line 68, in view
    return self.dispatch(request, *args, **kwargs)
  File "D:\python_env\dssms_env_for_win\lib\site-packages\django\views\generic\base.py", line 88, in dispatch
    return handler(request, *args, **kwargs)
  File "D:/python_env/dssms_project\company\views.py", line 134, in get
    companyname = request.session['companyname']
  File "D:\python_env\dssms_env_for_win\lib\site-packages\django\contrib\sessions\backends\base.py", line 50, in __getitem__
    return self._session[key]
KeyError: 'companyname'
2017-03-10 00:21:03,332 [Thread-10:13308] [django.request:182] [base:get_response] [WARNING]- Not Found: /login/<!--
